Workbook

Sheet 00 START HERE
A1: SAKSHI FORGE | ELECTROPOLISHED PIPE CITY-PAGE PROGRAMME
A2: 2,159 pages · 18 countries · one URL per city · built for uniqueness, not volume
A4: THE OBJECTIVE: GOOGLE TRUSTS THIS SITE
A5: What earns trust | B5: Not page count. A site earns trust when each page tells a reader something they could not get from the other 1,831 pages. Every mechanism in this workbook exists to force that outcome and to let you measure whether you achieved it.
A6: Structure decision | B6: ONE URL per city. Manufacturer, supplier and wholesaler are covered as three distinct H2 sections on that page, with their own body copy and their own FAQ. Sheet 03 shows all 21 keyword variants mapped to the section that targets them. Three URLs per city would have been the same buyer, same need, same answer - which is how Google defines a doorway page regardless of how differently the text is worded.
A8: THE UNIQUENESS ENGINE - WHAT CHANGED IN THIS VERSION
A9: The problem it solves | B9: A city page programme fails when the only variable is the city name. This build attacks that from four directions at once, so no two pages share a structure OR a data set.
A10: Mechanism | B10: How it works
A11: 8 unique data fields | B11: Every page carries 8 researched, city-only facts - estates, lead estate, industry mix, tag, gateway, transit note, local regulator, local proof point. These are the sentences that break when you swap the city name. | G11: 1,832 x 8 = 14,656 facts | H11: Informational uniqueness
A12: Pattern rotation | B12: Title suffix, meta template and H2 phrasing are assigned by position using coprime moduli, so structurally adjacent pages never share a template. | G12: 8 titles x 7 metas x 5 H2 sets | H12: Structural uniqueness
A13: Content angle | B13: The page shape changes with the dominant local industry. A Baddi page leads on formulations and packaging; a Kulim page leads on wafer fab and SEMI F19. Different sections, standards, grades, images. | G13: 8 angles | H13: Editorial uniqueness
A14: FAQ set assignment | B14: Each city is pre-assigned a named set from the 48-template bank, rotated so neighbouring cities overlap by less than half. | G14: 6 sets per tier | H14: Q&A uniqueness
A15: Measured, not claimed | B15: Column U of the CITY MASTER writes a pattern fingerprint for every page and column V counts how many other pages share it. Sheet 17 UNIQUENESS AUDIT turns that into a scorecard. If the number is wrong you will see it before Google does.
A17: THE HONEST COST
A18: Research load | B18: 484 rows arrive with real desk-researched data. 1,348 rows are seeded with placeholders and need local research. At roughly 20 minutes per city that is about 449 hours. You have said you will do it - sheet 13 is the worklist and it names the exact source to use for every state and country.
A19: The rule that protects you | B19: A row whose Data Status still reads VERIFY must not be published. Not as a thin page, not as a placeholder. Cut the city instead. One doorway page in a batch can pull the whole batch down with it.
A20: Pace | B20: 60 pages per week, 31 waves. This is not a launch, it is a build-out. The pace is itself a trust signal - and it gives you a feedback loop at wave 3 instead of a nasty surprise at page 1,800.
A22: SHEET INDEX
A23: 01 PAGE INVENTORY | B23: Counts by country and tier, live from the CITY MASTER.
A24: 02 CITY MASTER | B24: 1,832 rows. 8 research fields + rotation assignment + every generated SEO field.
A25: 03 KEYWORD MAP | B25: 21 keyword variants per city, each mapped to the page section that targets it.
A26: 04 PAGE BLUEPRINT | B26: Section-by-section wireframe with word budgets by tier.
A27: 05 CONTENT RULES | B27: The find-and-replace test and the five fields that carry uniqueness.
A28: 06 FAQ BANK | B28: 48 templates plus the FAQ SET assignment table.
A29: 07 SCHEMA LIBRARY | B29: Six JSON-LD blocks, copy-paste ready.
A30: 08 CALCULATORS | B30: Competitor tool audit plus build spec for 12 tools.
A31: 09 IMAGE & ALT | B31: Image slots, alt patterns, filename rules.
A32: 10 INTERNAL LINKING | B32: Silo depth, link counts, anchor diversity.
A33: 11 TECH SEO + HREFLANG | B33: Staged checklist. Stage 0 blocks everything.
A34: 12 SUPPORTING PAGES | B34: 327 non-city URLs.
... A39: 17 UNIQUENESS AUDIT | B39: Live scorecard proving the pages are not clones.

Sheet 01 PAGE INVENTORY
A1: PAGE INVENTORY BY MARKET
A2: Counts are COUNTIFS against the CITY MASTER - they move as you work
A4: Country | B4: Tier A | C4: Tier B | D4: Tier C | E4: Total city pages | F4: Data complete | G4: Research outstanding | H4: Waves | I4: Compliance anchor for this market
A5: India | B5: =COUNTIFS('02 CITY MASTER'!$B:$B,$A5,'02 CITY MASTER'!$F:$F,"A") -> 139 | C5: =COUNTIFS('02 CITY MASTER'!$B:$B,$A5,'02 CITY MASTER'!$F:$F,"B") -> 397 | D5: =COUNTIFS('02 CITY MASTER'!$B:$B,$A5,'02 CITY MASTER'!$F:$F,"C") -> 440 | E5: =SUM(B5:D5) -> 976 | F5: =COUNTIFS('02 CITY MASTER'!$B:$B,$A5,'02 CITY MASTER'!$G:$G,"VERIFIED") -> 139 | G5: =E5-F5 -> 837 | H5: =ROUNDUP(E5/60,0) -> 17 | I5: BIS; CDSCO/state FDA for pharma; FSSAI for food and dairy; buyer-specified ASTM A270 and ASME BPE
A6: UAE | B6: =COUNTIFS('02 CITY MASTER'!$B:$B,$A6,'02 CITY MASTER'!$F:$F,"A") -> 6 | C6: =COUNTIFS('02 CITY MASTER'!$B:$B,$A6,'02 CITY MASTER'!$F:$F,"B") -> 6 | D6: =COUNTIFS('02 CITY MASTER'!$B:$B,$A6,'02 CITY MASTER'!$F:$F,"C") -> 10 | E6: =SUM(B6:D6) -> 22 | F6: =COUNTIFS('02 CITY MASTER'!$B:$B,$A6,'02 CITY MASTER'!$G:$G,"VERIFIED") -> 12 | G6: =E6-F6 -> 10 | H6: =ROUNDUP(E6/60,0) -> 1 | I6: ASME BPE, ASTM A270, EN 10204 3.1, ESMA conformity, Halal-plant hygiene norms
A7: Saudi Arabia | B7: =COUNTIFS('02 CITY MASTER'!$B:$B,$A7,'02 CITY MASTER'!$F:$F,"A") -> 8 | C7: =COUNTIFS('02 CITY MASTER'!$B:$B,$A7,'02 CITY MASTER'!$F:$F,"B") -> 12 | D7: =COUNTIFS('02 CITY MASTER'!$B:$B,$A7,'02 CITY MASTER'!$F:$F,"C") -> 20 | E7: =SUM(B7:D7) -> 40 | F7: =COUNTIFS('02 CITY MASTER'!$B:$B,$A7,'02 CITY MASTER'!$G:$G,"VERIFIED") -> 20 | G7: =E7-F7 -> 20 | H7: =ROUNDUP(E7/60,0) -> 1 | I7: ASME BPE, ASTM A270, EN 10204 3.1, SASO / SABER certificate of conformity mandatory
A8: Qatar | B8: =COUNTIFS('02 CITY MASTER'!$B:$B,$A8,'02 CITY MASTER'!$F:$F,"A") -> 4 | C8: =COUNTIFS('02 CITY MASTER'!$B:$B,$A8,'02 CITY MASTER'!$F:$F,"B") -> 4 | D8: =COUNTIFS('02 CITY MASTER'!$B:$B,$A8,'02 CITY MASTER'!$F:$F,"C") -> 4 | E8: =SUM(B8:D8) -> 12 | F8: =COUNTIFS('02 CITY MASTER'!$B:$B,$A8,'02 CITY MASTER'!$G:$G,"VERIFIED") -> 8 | G8: =E8-F8 -> 4 | H8: =ROUNDUP(E8/60,0) -> 1 | I8: ASME BPE, ASTM A270, EN 10204 3.1, QS conformity
A9: Oman | B9: =COUNTIFS('02 CITY MASTER'!$B:$B,$A9,'02 CITY MASTER'!$F:$F,"A") -> 5 | C9: =COUNTIFS('02 CITY MASTER'!$B:$B,$A9,'02 CITY MASTER'!$F:$F,"B") -> 6 | D9: =COUNTIFS('02 CITY MASTER'!$B:$B,$A9,'02 CITY MASTER'!$F:$F,"C") -> 10 | E9: =SUM(B9:D9) -> 21 | F9: =COUNTIFS('02 CITY MASTER'!$B:$B,$A9,'02 CITY MASTER'!$G:$G,"VERIFIED") -> 11 | G9: =E9-F9 -> 10 | H9: =ROUNDUP(E9/60,0) -> 1 | I9: ASME BPE, ASTM A270, EN 10204 3.1, DGSM conformity
A10: Kuwait | B10: =COUNTIFS('02 CITY MASTER'!$B:$B,$A10,'02 CITY MASTER'!$F:$F,"A") -> 4 | C10: =COUNTIFS('02 CITY MASTER'!$B:$B,$A10,'02 CITY MASTER'!$F:$F,"B") -> 4 | D10: =COUNTIFS('02 CITY MASTER'!$B:$B,$A10,'02 CITY MASTER'!$F:$F,"C") -> 4 | E10: =SUM(B10:D10) -> 12 | F10: =COUNTIFS('02 CITY MASTER'!$B:$B,$A10,'02 CITY MASTER'!$G:$G,"VERIFIED") -> 8 | G10: =E10-F10 -> 4 | H10: =ROUNDUP(E10/60,0) -> 1 | I10: ASME BPE, ASTM A270, EN 10204 3.1, KUCAS conformity scheme
A11: Bahrain | B11: =COUNTIFS('02 CITY MASTER'!$B:$B,$A11,'02 CITY MASTER'!$F:$F,"A") -> 3 | C11: =COUNTIFS('02 CITY MASTER'!$B:$B,$A11,'02 CITY MASTER'!$F:$F,"B") -> 3 | D11: =COUNTIFS('02 CITY MASTER'!$B:$B,$A11,'02 CITY MASTER'!$F:$F,"C") -> 4 | E11: =SUM(B11:D11) -> 10 | F11: =COUNTIFS('02 CITY MASTER'!$B:$B,$A11,'02 CITY MASTER'!$G:$G,"VERIFIED") -> 6 | G11: =E11-F11 -> 4 | H11: =ROUNDUP(E11/60,0) -> 1 | I11: ASME BPE, ASTM A270, EN 10204 3.1, BSMD conformity
A12: USA | B12: =COUNTIFS('02 CITY MASTER'!$B:$B,$A12,'02 CITY MASTER'!$F:$F,"A") -> 16 | C12: =COUNTIFS('02 CITY MASTER'!$B:$B,$A12,'02 CITY MASTER'!$F:$F,"B") -> 30 | D12: =COUNTIFS('02 CITY MASTER'!$B:$B,$A12,'02 CITY MASTER'!$F:$F,"C") -> 60 | E12: =SUM(B12:D12) -> 106 | F12: =COUNTIFS('02 CITY MASTER'!$B:$B,$A12,'02 CITY MASTER'!$G:$G,"VERIFIED") -> 46 | G12: =E12-F12 -> 60 | H12: =ROUNDUP(E12/60,0) -> 2 | I12: ASME BPE SF1-SF6, ASTM A270 S2 pharma grade, 3-A Sanitary Standards, FDA 21 CFR 177, SEMI F19/F17 for semiconductor
A13: UK | B13: =COUNTIFS('02 CITY MASTER'!$B:$B,$A13,'02 CITY MASTER'!$F:$F,"A") -> 12 | C13: =COUNTIFS('02 CITY MASTER'!$B:$B,$A13,'02 CITY MASTER'!$F:$F,"B") -> 20 | D13: =COUNTIFS('02 CITY MASTER'!$B:$B,$A13,'02 CITY MASTER'!$F:$F,"C") -> 60 | E13: =SUM(B13:D13) -> 92 | F13: =COUNTIFS('02 CITY MASTER'!$B:$B,$A13,'02 CITY MASTER'!$G:$G,"VERIFIED") -> 32 | G13: =E13-F13 -> 60 | H13: =ROUNDUP(E13/60,0) -> 2 | I13: ASME BPE, ASTM A270, EN 10217-7, EN 10204 3.1, UKCA marking, PED/UK PER for pressure equipment
A14: Germany | B14: =COUNTIFS('02 CITY MASTER'!$B:$B,$A14,'02 CITY MASTER'!$F:$F,"A") -> 12 | C14: =COUNTIFS('02 CITY MASTER'!$B:$B,$A14,'02 CITY MASTER'!$F:$F,"B") -> 20 | D14: =COUNTIFS('02 CITY MASTER'!$B:$B,$A14,'02 CITY MASTER'!$F:$F,"C") -> 60 | E14: =SUM(B14:D14) -> 92 | F14: =COUNTIFS('02 CITY MASTER'!$B:$B,$A14,'02 CITY MASTER'!$G:$G,"VERIFIED") -> 32 | G14: =E14-F14 -> 60 | H14: =ROUNDUP(E14/60,0) -> 2 | I14: EN 10217-7, EN 10357, DIN 11850, ASME BPE, EN 10204 3.1/3.2, PED 2014/68/EU, EHEDG hygienic design
A15: Netherlands | B15: =COUNTIFS('02 CITY MASTER'!$B:$B,$A15,'02 CITY MASTER'!$F:$F,"A") -> 7 | C15: =COUNTIFS('02 CITY MASTER'!$B:$B,$A15,'02 CITY MASTER'!$F:$F,"B") -> 12 | D15: =COUNTIFS('02 CITY MASTER'!$B:$B,$A15,'02 CITY MASTER'!$F:$F,"C") -> 26 | E15: =SUM(B15:D15) -> 45 | F15: =COUNTIFS('02 CITY MASTER'!$B:$B,$A15,'02 CITY MASTER'!$G:$G,"VERIFIED") -> 19 | G15: =E15-F15 -> 26 | H15: =ROUNDUP(E15/60,0) -> 1 | I15: EN 10217-7, EN 10357, ASME BPE, EN 10204 3.1, PED 2014/68/EU, EHEDG
A16: Italy | B16: =COUNTIFS('02 CITY MASTER'!$B:$B,$A16,'02 CITY MASTER'!$F:$F,"A") -> 10 | C16: =COUNTIFS('02 CITY MASTER'!$B:$B,$A16,'02 CITY MASTER'!$F:$F,"B") -> 20 | D16: =COUNTIFS('02 CITY MASTER'!$B:$B,$A16,'02 CITY MASTER'!$F:$F,"C") -> 60 | E16: =SUM(B16:D16) -> 90 | F16: =COUNTIFS('02 CITY MASTER'!$B:$B,$A16,'02 CITY MASTER'!$G:$G,"VERIFIED") -> 30 | G16: =E16-F16 -> 60 | H16: =ROUNDUP(E16/60,0) -> 2 | I16: EN 10217-7, EN 10357, ASME BPE, EN 10204 3.1, PED 2014/68/EU, UNI hygienic norms
... A22: Vietnam | B22: =COUNTIFS('02 CITY MASTER'!$B:$B,$A22,'02 CITY MASTER'!$F:$F,"A") -> 8 | C22: =COUNTIFS('02 CITY MASTER'!$B:$B,$A22,'02 CITY MASTER'!$F:$F,"B") -> 14 | D22: =COUNTIFS('02 CITY MASTER'!$B:$B,$A22,'02 CITY MASTER'!$F:$F,"C") -> 36 | E22: =SUM(B22:D22) -> 58 | F22: =COUNTIFS('02 CITY MASTER'!$B:$B,$A22,'02 CITY MASTER'!$G:$G,"VERIFIED") -> 22 | G22: =E22-F22 -> 36 | H22: =ROUNDUP(E22/60,0) -> 1 | I22: ASME BPE, ASTM A270, TCVN conformity, SEMI F19/F17 for electronics fabs, EN 10204 3.1
A23: TOTAL | B23: =SUM(B5:B22) -> 270 | C23: =SUM(C5:C22) -> 611 | D23: =SUM(D5:D22) -> 951 | E23: =SUM(E5:E22) -> 1832 | F23: =SUM(F5:F22) -> 484 | G23: =SUM(G5:G22) -> 1348
A25: EXPORT CONTEXT PER MARKET - use these on the country hub and in FAQ answers
A26: Country | B26: Gateway port | C26: Sea transit from Nhava Sheva | D26: Incoterm | E26: Regulator | F26: Duty / customs note
A27: UAE | B27: Jebel Ali Port | C27: 10-14 days sea from Nhava Sheva to Jebel Ali | D27: CIF Jebel Ali | E27: MOIAT / ESMA (Emirates Authority for Standardization) | F27: 0-5% GCC common external tariff; India-UAE CEPA preferential rates apply
A28: Saudi Arabia | B28: King Abdulaziz Port Dammam / Jeddah Islamic Port | C28: 12-16 days sea from Nhava Sheva to Dammam | D28: CIF Dammam / Jeddah | E28: SASO with SABER platform registration | F28: 5-15% depending on HS code; SABER CoC required at customs
A29: Qatar | B29: Hamad Port Doha | C29: 12-15 days sea from Nhava Sheva to Hamad Port | D29: CIF Hamad Port | E29: Qatar General Organization for Standards and Metrology | F29: 5% GCC common external tariff
A30: Oman | B30: Port of Sohar / Port of Salalah | C30: 7-10 days sea from Nhava Sheva to Sohar | D30: CIF Sohar / Salalah | E30: Directorate General for Standards and Metrology | F30: 5% GCC common external tariff
A31: Kuwait | B31: Shuwaikh Port / Shuaiba Port | C31: 14-18 days sea from Nhava Sheva to Shuwaikh | D31: CIF Shuwaikh | E31: Public Authority for Industry (PAI) under KUCAS | F31: 5% GCC common external tariff; KUCAS TIR required
A32: Bahrain | B32: Khalifa Bin Salman Port | C32: 13-17 days sea from Nhava Sheva to Khalifa Bin Salman Port | D32: CIF Khalifa Bin Salman | E32: Bahrain Standards and Metrology Directorate | F32: 5% GCC common external tariff
A33: USA | B33: Port of New York/Newark, Port of Houston, Port of LA-Long Beach | C33: 28-35 days sea from Nhava Sheva to US East Coast | D33: CIF / DDP US port | E33: FDA (food/pharma contact), ASME BPE, 3-A SSI | F33: Section 232 steel tariff plus MFN rate; verify current HTS 7306.40 treatment before quoting
A34: UK | B34: Port of Felixstowe / Southampton | C34: 22-28 days sea from Nhava Sheva to Felixstowe | D34: CIF Felixstowe / Southampton | E34: UKCA regime post-Brexit; UK Pressure Equipment (Safety) Regulations | F34: UK Global Tariff; check TRQ on steel
A35: Germany | B35: Port of Hamburg / Bremerhaven | C35: 24-30 days sea from Nhava Sheva to Hamburg | D35: CIF Hamburg / Rotterdam | E35: CE marking under PED 2014/68/EU; AD 2000-Merkblatt for pressure parts | F35: EU CBAM reporting applies to steel from Oct 2023; verify current phase
A36: Netherlands | B36: Port of Rotterdam | C36: 23-29 days sea from Nhava Sheva to Rotterdam | D36: CIF Rotterdam | E36: CE marking under PED 2014/68/EU | F36: EU CBAM reporting applies to steel imports
A37: Italy | B37: Port of Genoa / Port of Trieste | C37: 18-24 days sea from Nhava Sheva to Genoa | D37: CIF Genoa / Trieste | E37: CE marking under PED 2014/68/EU | F37: EU CBAM reporting applies to steel imports
... A43: Vietnam | B43: Hai Phong Port / Cat Lai Ho Chi Minh City | C43: 12-16 days sea from Nhava Sheva to Hai Phong | D43: CIF Hai Phong / Cat Lai | E43: STAMEQ / Ministry of Science and Technology | F43: AIFTA preferential tariff applies

Sheet 02 CITY MASTER
A1: CITY MASTER
A2: AMBER = research and edit by hand. WHITE = formula, never type over. Columns H-O are what make each page unique.
A3: Page ID | B3: Country | C3: State / Region | D3: City | E3: Display Name | F3: Tier | G3: Data Status | H3: 1. Industrial Estates (all real names) | I3: 2. Lead Estate (short) | J3: 3. Dominant Industry Mix | K3: 4. Short Industry Tag | L3: 5. Logistics Gateway | M3: 6. Transit Note | N3: 7. Local Standard / Regulator | O3: 8. Local Proof Point (one true sentence) | P3: Content Angle | Q3: Title Pattern | R3: Meta Pattern | S3: H2 Set | T3: FAQ Set | U3: Pattern Fingerprint | V3: Pages sharing this fingerprint | W3: Slug Override | X3: URL Slug | Y3: Full URL | Z3: Title Tag | AA3: Title QC | AB3: Meta Description | AC3: Meta QC | AD3: H1 | AE3: H2 - Manufacturer | AF3: H2 - Supplier | AG3: H2 - Wholesaler | AH3: Meta Keywords | AI3: OG / Twitter Title | AJ3: OG / Twitter Description | AK3: Hero Image ALT | AL3: Hero Image Title | AM3: Breadcrumb Trail | AN3: Word Target | AO3: Min FAQs | AP3: Min Internal Links | AQ3: Rollout Wave | AR3: Title Override | AS3: Meta Description Override | AT3: Build Status | AU3: Indexed in GSC
A4: CTY-0001 | B4: India | C4: Uttar Pradesh | D4: Agra | E4: Agra | F4: A | G4: VERIFIED | H4: Sikandra Industrial Area, Runakta UPSIDA | I4: Sikandra Industrial Area | J4: Leather, food processing, engineering | K4: food processing | L4: ICD Dadri (180 km) | M4: 1-2 day road transit from our Mumbai works | N4: FSSAI licensing; 3-A Sanitary Standards on product-contact lines | O4: VERIFY | P4: =IF($K4="VERIFY","VERIFY",IF(ISNUMBER(SEARCH("semicon",$K4)),"SEMI",IF(ISNUMBER(SEARCH("electronic",$K4)),"SEMI",IF(ISNUMBER(SEARCH("biotech",$K4)),"BIOTECH",IF(ISNUMBER(SEARCH("pharma",$K4)),"PHARMA",IF(ISNUMBER(SEARCH("medical",$K4)),"PHARMA",IF(ISNUMBER(SEARCH("dairy",$K4)),"DAIRY",IF(ISNUMBER(SEARCH("brewery",$K4)),"BREWERY",IF(ISNUMBER(SEARCH("food",$K4)),"FOOD",IF(ISNUMBER(SEARCH("personal care",$K4)),"FOOD",IF(ISNUMBER(SEARCH("chemical",$K4)),"CHEM",IF(ISNUMBER(SEARCH("refining",$K4)),"CHEM",IF(ISNUMBER(SEARCH("petrochem",$K4)),"CHEM",IF(ISNUMBER(SEARCH("fertilis",$K4)),"CHEM",IF(ISNUMBER(SEARCH("water",$K4)),"CHEM","GENERAL"))))))))))))))) -> FOOD | Q4: =MOD(ROW()-4,8)+1 -> 1 | R4: =MOD(ROW()-4,7)+1 -> 1 | S4: =MOD(ROW()-4,5)+1 -> 1 | T4: =$F4&"-"&(MOD(ROW()-4,6)+1) -> A-1 | U4: ="T"&$Q4&"-M"&$R4&"-H"&$S4&"-F"&$T4&"-"&$P4 -> T1-M1-H1-FA-1-FOOD | V4: =COUNTIF($U$4:$U$1835,$U4)-1 -> 0 | X4: =IF($W4<>"",$W4,IF($B4="India",LOWER(SUBSTITUTE(SUBSTITUTE($D4," ","-"),".","")),LOWER(SUBSTITUTE(SUBSTITUTE($D4," ","-"),".",""))&"-"&LOWER(SUBSTITUTE($B4," ","-")))) -> agra | Y4: ="https://steelmanufacturer.in/market-area/electropolished-pipes-manufacturer-in-"&$X4&"/" -> https://steelmanufacturer.in/market-area/electropolished-pipes-manufacturer-in-agra/ | Z4: =IF($AR4<>"",$AR4,IF(LEN("Electropolished Pipes Manufacturer in "&$E4&CHOOSE($Q4," | Sakshi Forge"," - ASTM A270 & ASME BPE"," | EP Tube Supplier"," - SS 304/316L EP Tube"," | Sanitary Tube Supply"," - Mill Certified Supply"," | ASME BPE SF1-SF4"," - EP Tube Stockist"))<=65,"Electropolished Pipes Manufacturer in "&$E4&CHOOSE($Q4," | Sakshi Forge"," - ASTM A270 & ASME BPE"," | EP Tube Supplier"," - SS 304/316L EP Tube"," | Sanitary Tube Supply"," - Mill Certified Supply"," | ASME BPE SF1-SF4"," - EP Tube Stockist"),"Electropolished Pipes Manufacturer in "&$E4)) -> Electropolished Pipes Manufacturer in Agra | Sakshi Forge | AA4: =IF(LEN($Z4)>65,"TRIM ("&LEN($Z4)&")",IF(LEN($Z4)<35,"SHORT ("&LEN($Z4)&")","OK ("&LEN($Z4)&")")) -> OK (57) | AB4: =IF($AS4<>"",$AS4,CHOOSE($R4,"EP-finished SS 304/316L pipes & tubes for "&$K4&" plants in "&$E4&". ASTM A270, ASME BPE SF1-SF4, EN 10204 3.1 MTC. PMI tested.","Electropolished tube supply to "&$I4&", "&$E4&". Ra from 0.25 um, SF4 finish, mill test certificate with every lot.","EP stainless tube for "&$K4&" lines in "&$E4&". "&$M4&". ASTM A270 S2, PMI tested, EN 10204 3.1.","Sanitary electropolished pipes in "&$E4&" for "&$K4&" plants. ASME BPE SF1-SF4, orbital-weld ready, 3.1 MTC. Mumbai-made.","Manufacturer of electropolished SS 316L tube serving "&$E4&". "&$M4&". Ra 0.25-0.5 um, EN 10204 3.1 MTC.",IF(LEN("EP tube and pipe for "&$K4&" plants around "&$I4&", "&$E4&". Made at our Mumbai works to ASTM A270 and ASME BPE SF1-SF4, with 3.1 MTC.")<=160,"EP tube and pipe for "&$K4&" plants around "&$I4&", "&$E4&". Made at our Mumbai works to ASTM A270 and ASME BPE SF1-SF4, with 3.1 MTC.","EP tube and pipe for "&$K4&" plants around "&$I4&", "&$E4&". ASTM A270, ASME BPE SF1-SF4, EN 10204 3.1 MTC."),"Electropolished pipes in "&$E4&": 304, 304L, 316 and 316L in SF1-SF4. "&$M4&". Mill certified.")) -> EP-finished SS 304/316L pipes & tubes for food processing plants in Agra. ASTM A270, ASME BPE SF1-SF4, EN 10204 3.1 MTC. PMI tested. | AC4: =IF($G4="VERIFY","PENDING RESEARCH",IF(LEN($AB4)>160,"TRIM ("&LEN($AB4)&")",IF(LEN($AB4)<110,"SHORT ("&LEN($AB4)&")","OK ("&LEN($AB4)&")"))) -> OK (132) | AD4: ="Electropolished Pipes Manufacturer in "&$E4 -> Electropolished Pipes Manufacturer in Agra | AE4: =CHOOSE($S4,"Electropolished Pipe & Tube Manufacturing for "&$E4&" - Grades, Finishes & Certification","How We Manufacture Electropolished Tube for "&$E4&" Plants","Electropolished Pipes Manufacturer in "&$E4&" - Our Process & Capability","Manufacturing Electropolished SS Tube for "&$E4&": The Standards We Build To","Electropolished Tube Manufacturing Capability Serving "&$E4) -> Electropolished Pipe & Tube Manufacturing for Agra - Grades, Finishes & Certification | AF4: =CHOOSE($S4,"Electropolished Pipes Supplier in "&$E4&" - Stock Sizes, Lead Time & Delivery","Supplying Electropolished Pipes in "&$E4&": Availability, Sizes & Dispatch","Electropolished Pipes Supplier in "&$E4&" - What We Hold in Stock","Electropolished Pipe Supply Into "&$E4&" - Certification & Transit","Electropolished Pipes Supplier in "&$E4&" - From Order to Delivery") -> Electropolished Pipes Supplier in Agra - Stock Sizes, Lead Time & Delivery | AG4: =CHOOSE($S4,"Electropolished Pipes Wholesaler & Stockist in "&$E4&" - Bulk & Project Pricing","Wholesale Electropolished Pipe Supply for "&$E4&" Projects","Bulk & Wholesale Electropolished Pipe Rates for "&$E4&" Buyers","Electropolished Pipes Wholesaler in "&$E4&" - Project Quantities & Terms","Stockist & Wholesale Supply of Electropolished Pipes in "&$E4) -> Electropolished Pipes Wholesaler & Stockist in Agra - Bulk & Project Pricing | AH4: ="electropolished pipes manufacturer in "&$D4&", electropolished pipes supplier in "&$D4&", electropolished pipes wholesaler in "&$D4&", electropolished tube manufacturer "&$D4&", EP pipe supplier "&$D4&", sanitary tube supplier "&$D4&", ASME BPE tubing "&$D4&", ASTM A270 tube "&$D4&", SS 316L electropolished pipe "&$D4 -> electropolished pipes manufacturer in Agra, electropolished pipes supplier in Agra, electropolished pipes wholesaler in Agra, electropolished tube manufacturer Agra, EP pipe supplier Agra, sanitary tube supplier Agra, ASME BPE tubing Agra, ASTM A270 tube Agra, SS 316L electropolished pipe Agra | AI4: ="Electropolished Pipes Manufacturer & Supplier in "&$E4 -> Electropolished Pipes Manufacturer & Supplier in Agra | AJ4: ="EP-finished SS 304/316L pipes and tubes for "&$K4&" plants in "&$E4&". ASME BPE SF1-SF4, Ra from 0.25 um, EN 10204 3.1 certificate with every lot." -> EP-finished SS 304/316L pipes and tubes for food processing plants in Agra. ASME BPE SF1-SF4, Ra from 0.25 um, EN 10204 3.1 certificate with every lot. | AK4: ="Electropolished stainless steel pipes supplied by Sakshi Forge to "&$K4&" plants at "&$I4&", "&$E4 -> Electropolished stainless steel pipes supplied by Sakshi Forge to food processing plants at Sikandra Industrial Area, Agra | AL4: ="Electropolished SS 316L tube stock for "&$E4&" - Sakshi Forge" -> Electropolished SS 316L tube stock for Agra - Sakshi Forge | AM4: ="Home > Market Area > "&$B4&" > "&$C4&" > "&$D4 -> Home > Market Area > India > Uttar Pradesh > Agra | AN4: =IF($F4="A",1400,IF($F4="B",1000,750)) -> 1400 | AO4: =IF($F4="A",10,IF($F4="B",8,6)) -> 10 | AP4: =IF($F4="A",12,IF($F4="B",8,6)) -> 12 | AQ4: =ROUNDUP((ROW()-3)/60,0) -> 1 | AT4: Not started
A5: CTY-0002 | B5: India | C5: Gujarat | D5: Ahmedabad | E5: Ahmedabad | F5: A | G5: VERIFIED | H5: Odhav GIDC, Vatva GIDC, Naroda GIDC, Changodar | I5: Odhav GIDC | J5: Pharmaceutical formulations, dyes and intermediates, food processing | K5: pharma | L5: Mundra Port (350 km) | M5: 2-3 day road transit from our Mumbai works | N5: CDSCO + state FDA licensed plants; WHO-GMP and USFDA documentation common | O5: VERIFY | P5: =IF($K5="VERIFY","VERIFY",IF(ISNUMBER(SEARCH("semicon",$K5)),"SEMI",IF(ISNUMBER(SEARCH("electronic",$K5)),"SEMI",IF(ISNUMBER(SEARCH("biotech",$K5)),"BIOTECH",IF(ISNUMBER(SEARCH("pharma",$K5)),"PHARMA",IF(ISNUMBER(SEARCH("medical",$K5)),"PHARMA",IF(ISNUMBER(SEARCH("dairy",$K5)),"DAIRY",IF(ISNUMBER(SEARCH("brewery",$K5)),"BREWERY",IF(ISNUMBER(SEARCH("food",$K5)),"FOOD",IF(ISNUMBER(SEARCH("personal care",$K5)),"FOOD",IF(ISNUMBER(SEARCH("chemical",$K5)),"CHEM",IF(ISNUMBER(SEARCH("refining",$K5)),"CHEM",IF(ISNUMBER(SEARCH("petrochem",$K5)),"CHEM",IF(ISNUMBER(SEARCH("fertilis",$K5)),"CHEM",IF(ISNUMBER(SEARCH("water",$K5)),"CHEM","GENERAL"))))))))))))))) -> PHARMA | Q5: =MOD(ROW()-4,8)+1 -> 2 | R5: =MOD(ROW()-4,7)+1 -> 2 | S5: =MOD(ROW()-4,5)+1 -> 2 | T5: =$F5&"-"&(MOD(ROW()-4,6)+1) -> A-2 | U5: ="T"&$Q5&"-M"&$R5&"-H"&$S5&"-F"&$T5&"-"&$P5 -> T2-M2-H2-FA-2-PHARMA | V5: =COUNTIF($U$4:$U$1835,$U5)-1 -> 0 | X5: =IF($W5<>"",$W5,IF($B5="India",LOWER(SUBSTITUTE(SUBSTITUTE($D5," ","-"),".","")),LOWER(SUBSTITUTE(SUBSTITUTE($D5," ","-"),".",""))&"-"&LOWER(SUBSTITUTE($B5," ","-")))) -> ahmedabad | Y5: ="https://steelmanufacturer.in/market-area/electropolished-pipes-manufacturer-in-"&$X5&"/" -> https://steelmanufacturer.in/market-area/electropolished-pipes-manufacturer-in-ahmedabad/ | Z5: =IF($AR5<>"",$AR5,IF(LEN("Electropolished Pipes Manufacturer in "&$E5&CHOOSE($Q5," | Sakshi Forge"," - ASTM A270 & ASME BPE"," | EP Tube Supplier"," - SS 304/316L EP Tube"," | Sanitary Tube Supply"," - Mill Certified Supply"," | ASME BPE SF1-SF4"," - EP Tube Stockist"))<=65,"Electropolished Pipes Manufacturer in "&$E5&CHOOSE($Q5," | Sakshi Forge"," - ASTM A270 & ASME BPE"," | EP Tube Supplier"," - SS 304/316L EP Tube"," | Sanitary Tube Supply"," - Mill Certified Supply"," | ASME BPE SF1-SF4"," - EP Tube Stockist"),"Electropolished Pipes Manufacturer in "&$E5)) -> Electropolished Pipes Manufacturer in Ahmedabad | AA5: =IF(LEN($Z5)>65,"TRIM ("&LEN($Z5)&")",IF(LEN($Z5)<35,"SHORT ("&LEN($Z5)&")","OK ("&LEN($Z5)&")")) -> OK (47) | AB5: =IF($AS5<>"",$AS5,CHOOSE($R5,"EP-finished SS 304/316L pipes & tubes for "&$K5&" plants in "&$E5&". ASTM A270, ASME BPE SF1-SF4, EN 10204 3.1 MTC. PMI tested.","Electropolished tube supply to "&$I5&", "&$E5&". Ra from 0.25 um, SF4 finish, mill test certificate with every lot.","EP stainless tube for "&$K5&" lines in "&$E5&". "&$M5&". ASTM A270 S2, PMI tested, EN 10204 3.1.","Sanitary electropolished pipes in "&$E5&" for "&$K5&" plants. ASME BPE SF1-SF4, orbital-weld ready, 3.1 MTC. Mumbai-made.","Manufacturer of electropolished SS 316L tube serving "&$E5&". "&$M5&". Ra 0.25-0.5 um, EN 10204 3.1 MTC.",IF(LEN("EP tube and pipe for "&$K5&" plants around "&$I5&", "&$E5&". Made at our Mumbai works to ASTM A270 and ASME BPE SF1-SF4, with 3.1 MTC.")<=160,"EP tube and pipe for "&$K5&" plants around "&$I5&", "&$E5&". Made at our Mumbai works to ASTM A270 and ASME BPE SF1-SF4, with 3.1 MTC.","EP tube and pipe for "&$K5&" plants around "&$I5&", "&$E5&". ASTM A270, ASME BPE SF1-SF4, EN 10204 3.1 MTC."),"Electropolished pipes in "&$E5&": 304, 304L, 316 and 316L in SF1-SF4. "&$M5&". Mill certified.")) -> Electropolished tube supply to Odhav GIDC, Ahmedabad. Ra from 0.25 um, SF4 finish, mill test certificate with every lot. | AC5: =IF($G5="VERIFY","PENDING RESEARCH",IF(LEN($AB5)>160,"TRIM ("&LEN($AB5)&")",IF(LEN($AB5)<110,"SHORT ("&LEN($AB5)&")","OK ("&LEN($AB5)&")"))) -> OK (120) | AD5: ="Electropolished Pipes Manufacturer in "&$E5 -> Electropolished Pipes Manufacturer in Ahmedabad | AE5: =CHOOSE($S5,"Electropolished Pipe & Tube Manufacturing for "&$E5&" - Grades, Finishes & Certification","How We Manufacture Electropolished Tube for "&$E5&" Plants","Electropolished Pipes Manufacturer in "&$E5&" - Our Process & Capability","Manufacturing Electropolished SS Tube for "&$E5&": The Standards We Build To","Electropolished Tube Manufacturing Capability Serving "&$E5) -> How We Manufacture Electropolished Tube for Ahmedabad Plants | AF5: =CHOOSE($S5,"Electropolished Pipes Supplier in "&$E5&" - Stock Sizes, Lead Time & Delivery","Supplying Electropolished Pipes in "&$E5&": Availability, Sizes & Dispatch","Electropolished Pipes Supplier in "&$E5&" - What We Hold in Stock","Electropolished Pipe Supply Into "&$E5&" - Certification & Transit","Electropolished Pipes Supplier in "&$E5&" - From Order to Delivery") -> Supplying Electropolished Pipes in Ahmedabad: Availability, Sizes & Dispatch | AG5: =CHOOSE($S5,"Electropolished Pipes Wholesaler & Stockist in "&$E5&" - Bulk & Project Pricing","Wholesale Electropolished Pipe Supply for "&$E5&" Projects","Bulk & Wholesale Electropolished Pipe Rates for "&$E5&" Buyers","Electropolished Pipes Wholesaler in "&$E5&" - Project Quantities & Terms","Stockist & Wholesale Supply of Electropolished Pipes in "&$E5) -> Wholesale Electropolished Pipe Supply for Ahmedabad Projects | AH5: ="electropolished pipes manufacturer in "&$D5&", electropolished pipes supplier in "&$D5&", electropolished pipes wholesaler in "&$D5&", electropolished tube manufacturer "&$D5&", EP pipe supplier "&$D5&", sanitary tube supplier "&$D5&", ASME BPE tubing "&$D5&", ASTM A270 tube "&$D5&", SS 316L electropolished pipe "&$D5 -> electropolished pipes manufacturer in Ahmedabad, electropolished pipes supplier in Ahmedabad, electropolished pipes wholesaler in Ahmedabad, electropolished tube manufacturer Ahmedabad, EP pipe supplier Ahmedabad, sanitary tube supplier Ahmedabad, ASME BPE tubing Ahmedabad, ASTM A270 tube Ahmedabad, SS 316L electropolished pipe Ahmedabad | AI5: ="Electropolished Pipes Manufacturer & Supplier in "&$E5 -> Electropolished Pipes Manufacturer & Supplier in Ahmedabad | AJ5: ="EP-finished SS 304/316L pipes and tubes for "&$K5&" plants in "&$E5&". ASME BPE SF1-SF4, Ra from 0.25 um, EN 10204 3.1 certificate with every lot." -> EP-finished SS 304/316L pipes and tubes for pharma plants in Ahmedabad. ASME BPE SF1-SF4, Ra from 0.25 um, EN 10204 3.1 certificate with every lot. | AK5: ="Electropolished stainless steel pipes supplied by Sakshi Forge to "&$K5&" plants at "&$I5&", "&$E5 -> Electropolished stainless steel pipes supplied by Sakshi Forge to pharma plants at Odhav GIDC, Ahmedabad | AL5: ="Electropolished SS 316L tube stock for "&$E5&" - Sakshi Forge" -> Electropolished SS 316L tube stock for Ahmedabad - Sakshi Forge | AM5: ="Home > Market Area > "&$B5&" > "&$C5&" > "&$D5 -> Home > Market Area > India > Gujarat > Ahmedabad | AN5: =IF($F5="A",1400,IF($F5="B",1000,750)) -> 1400 | AO5: =IF($F5="A",10,IF($F5="B",8,6)) -> 10 | AP5: =IF($F5="A",12,IF($F5="B",8,6)) -> 12 | AQ5: =ROUNDUP((ROW()-3)/60,0) -> 1 | AT5: Not started
A6: CTY-0003 | B6: India | C6: Rajasthan | D6: Alwar | E6: Alwar | F6: A | G6: VERIFIED | H6: Alwar RIICO, MIA Alwar, Neemrana Japanese Zone | I6: Alwar RIICO | J6: Automotive, engineering, food processing | K6: food processing | L6: ICD Tughlakabad (150 km) | M6: 1-2 day road transit from our Mumbai works | N6: FSSAI licensing; 3-A Sanitary Standards on product-contact lines | O6: VERIFY | P6: =IF($K6="VERIFY","VERIFY",IF(ISNUMBER(SEARCH("semicon",$K6)),"SEMI",IF(ISNUMBER(SEARCH("electronic",$K6)),"SEMI",IF(ISNUMBER(SEARCH("biotech",$K6)),"BIOTECH",IF(ISNUMBER(SEARCH("pharma",$K6)),"PHARMA",IF(ISNUMBER(SEARCH("medical",$K6)),"PHARMA",IF(ISNUMBER(SEARCH("dairy",$K6)),"DAIRY",IF(ISNUMBER(SEARCH("brewery",$K6)),"BREWERY",IF(ISNUMBER(SEARCH("food",$K6)),"FOOD",IF(ISNUMBER(SEARCH("personal care",$K6)),"FOOD",IF(ISNUMBER(SEARCH("chemical",$K6)),"CHEM",IF(ISNUMBER(SEARCH("refining",$K6)),"CHEM",IF(ISNUMBER(SEARCH("petrochem",$K6)),"CHEM",IF(ISNUMBER(SEARCH("fertilis",$K6)),"CHEM",IF(ISNUMBER(SEARCH("water",$K6)),"CHEM","GENERAL"))))))))))))))) -> FOOD | Q6: =MOD(ROW()-4,8)+1 -> 3 | R6: =MOD(ROW()-4,7)+1 -> 3 | S6: =MOD(ROW()-4,5)+1 -> 3 | T6: =$F6&"-"&(MOD(ROW()-4,6)+1) -> A-3 | U6: ="T"&$Q6&"-M"&$R6&"-H"&$S6&"-F"&$T6&"-"&$P6 -> T3-M3-H3-FA-3-FOOD | V6: =COUNTIF($U$4:$U$1835,$U6)-1 -> 0 | X6: =IF($W6<>"",$W6,IF($B6="India",LOWER(SUBSTITUTE(SUBSTITUTE($D6," ","-"),".","")),LOWER(SUBSTITUTE(SUBSTITUTE($D6," ","-"),".",""))&"-"&LOWER(SUBSTITUTE($B6," ","-")))) -> alwar | Y6: ="https://steelmanufacturer.in/market-area/electropolished-pipes-manufacturer-in-"&$X6&"/" -> https://steelmanufacturer.in/market-area/electropolished-pipes-manufacturer-in-alwar/ | Z6: =IF($AR6<>"",$AR6,IF(LEN("Electropolished Pipes Manufacturer in "&$E6&CHOOSE($Q6," | Sakshi Forge"," - ASTM A270 & ASME BPE"," | EP Tube Supplier"," - SS 304/316L EP Tube"," | Sanitary Tube Supply"," - Mill Certified Supply"," | ASME BPE SF1-SF4"," - EP Tube Stockist"))<=65,"Electropolished Pipes Manufacturer in "&$E6&CHOOSE($Q6," | Sakshi Forge"," - ASTM A270 & ASME BPE"," | EP Tube Supplier"," - SS 304/316L EP Tube"," | Sanitary Tube Supply"," - Mill Certified Supply"," | ASME BPE SF1-SF4"," - EP Tube Stockist"),"Electropolished Pipes Manufacturer in "&$E6)) -> Electropolished Pipes Manufacturer in Alwar | EP Tube Supplier | AA6: =IF(LEN($Z6)>65,"TRIM ("&LEN($Z6)&")",IF(LEN($Z6)<35,"SHORT ("&LEN($Z6)&")","OK ("&LEN($Z6)&")")) -> OK (62) | AB6: =IF($AS6<>"",$AS6,CHOOSE($R6,"EP-finished SS 304/316L pipes & tubes for "&$K6&" plants in "&$E6&". ASTM A270, ASME BPE SF1-SF4, EN 10204 3.1 MTC. PMI tested.","Electropolished tube supply to "&$I6&", "&$E6&". Ra from 0.25 um, SF4 finish, mill test certificate with every lot.","EP stainless tube for "&$K6&" lines in "&$E6&". "&$M6&". ASTM A270 S2, PMI tested, EN 10204 3.1.","Sanitary electropolished pipes in "&$E6&" for "&$K6&" plants. ASME BPE SF1-SF4, orbital-weld ready, 3.1 MTC. Mumbai-made.","Manufacturer of electropolished SS 316L tube serving "&$E6&". "&$M6&". Ra 0.25-0.5 um, EN 10204 3.1 MTC.",IF(LEN("EP tube and pipe for "&$K6&" plants around "&$I6&", "&$E6&". Made at our Mumbai works to ASTM A270 and ASME BPE SF1-SF4, with 3.1 MTC.")<=160,"EP tube and pipe for "&$K6&" plants around "&$I6&", "&$E6&". Made at our Mumbai works to ASTM A270 and ASME BPE SF1-SF4, with 3.1 MTC.","EP tube and pipe for "&$K6&" plants around "&$I6&", "&$E6&". ASTM A270, ASME BPE SF1-SF4, EN 10204 3.1 MTC."),"Electropolished pipes in "&$E6&": 304, 304L, 316 and 316L in SF1-SF4. "&$M6&". Mill certified.")) -> EP stainless tube for food processing lines in Alwar. 1-2 day road transit from our Mumbai works. ASTM A270 S2, PMI tested, EN 10204 3.1. | AC6: =IF($G6="VERIFY","PENDING RESEARCH",IF(LEN($AB6)>160,"TRIM ("&LEN($AB6)&")",IF(LEN($AB6)<110,"SHORT ("&LEN($AB6)&")","OK ("&LEN($AB6)&")"))) -> OK (137) | AD6: ="Electropolished Pipes Manufacturer in "&$E6 -> Electropolished Pipes Manufacturer in Alwar | AE6: =CHOOSE($S6,"Electropolished Pipe & Tube Manufacturing for "&$E6&" - Grades, Finishes & Certification","How We Manufacture Electropolished Tube for "&$E6&" Plants","Electropolished Pipes Manufacturer in "&$E6&" - Our Process & Capability","Manufacturing Electropolished SS Tube for "&$E6&": The Standards We Build To","Electropolished Tube Manufacturing Capability Serving "&$E6) -> Electropolished Pipes Manufacturer in Alwar - Our Process & Capability | AF6: =CHOOSE($S6,"Electropolished Pipes Supplier in "&$E6&" - Stock Sizes, Lead Time & Delivery","Supplying Electropolished Pipes in "&$E6&": Availability, Sizes & Dispatch","Electropolished Pipes Supplier in "&$E6&" - What We Hold in Stock","Electropolished Pipe Supply Into "&$E6&" - Certification & Transit","Electropolished Pipes Supplier in "&$E6&" - From Order to Delivery") -> Electropolished Pipes Supplier in Alwar - What We Hold in Stock | AG6: =CHOOSE($S6,"Electropolished Pipes Wholesaler & Stockist in "&$E6&" - Bulk & Project Pricing","Wholesale Electropolished Pipe Supply for "&$E6&" Projects","Bulk & Wholesale Electropolished Pipe Rates for "&$E6&" Buyers","Electropolished Pipes Wholesaler in "&$E6&" - Project Quantities & Terms","Stockist & Wholesale Supply of Electropolished Pipes in "&$E6) -> Bulk & Wholesale Electropolished Pipe Rates for Alwar Buyers | AH6: ="electropolished pipes manufacturer in "&$D6&", electropolished pipes supplier in "&$D6&", electropolished pipes wholesaler in "&$D6&", electropolished tube manufacturer "&$D6&", EP pipe supplier "&$D6&", sanitary tube supplier "&$D6&", ASME BPE tubing "&$D6&", ASTM A270 tube "&$D6&", SS 316L electropolished pipe "&$D6 -> electropolished pipes manufacturer in Alwar, electropolished pipes supplier in Alwar, electropolished pipes wholesaler in Alwar, electropolished tube manufacturer Alwar, EP pipe supplier Alwar, sanitary tube supplier Alwar, ASME BPE tubing Alwar, ASTM A270 tube Alwar, SS 316L electropolished pipe Alwar | AI6: ="Electropolished Pipes Manufacturer & Supplier in "&$E6 -> Electropolished Pipes Manufacturer & Supplier in Alwar | AJ6: ="EP-finished SS 304/316L pipes and tubes for "&$K6&" plants in "&$E6&". ASME BPE SF1-SF4, Ra from 0.25 um, EN 10204 3.1 certificate with every lot." -> EP-finished SS 304/316L pipes and tubes for food processing plants in Alwar. ASME BPE SF1-SF4, Ra from 0.25 um, EN 10204 3.1 certificate with every lot. | AK6: ="Electropolished stainless steel pipes supplied by Sakshi Forge to "&$K6&" plants at "&$I6&", "&$E6 -> Electropolished stainless steel pipes supplied by Sakshi Forge to food processing plants at Alwar RIICO, Alwar | AL6: ="Electropolished SS 316L tube stock for "&$E6&" - Sakshi Forge" -> Electropolished SS 316L tube stock for Alwar - Sakshi Forge | AM6: ="Home > Market Area > "&$B6&" > "&$C6&" > "&$D6 -> Home > Market Area > India > Rajasthan > Alwar | AN6: =IF($F6="A",1400,IF($F6="B",1000,750)) -> 1400 | AO6: =IF($F6="A",10,IF($F6="B",8,6)) -> 10 | AP6: =IF($F6="A",12,IF($F6="B",8,6)) -> 12 | AQ6: =ROUNDUP((ROW()-3)/60,0) -> 1 | AT6: Not started
A7: CTY-0004 | B7: India | C7: Haryana | D7: Ambala | E7: Ambala | F7: A | G7: VERIFIED | H7: Ambala Industrial Area, Ambala Cantt Estate | I7: Ambala Industrial Area | J7: Scientific instruments, engineering, mixers | K7: engineering & process | L7: ICD Ludhiana (170 km) | M7: 1-2 day road transit from our Mumbai works | N7: BIS and buyer-specified ASTM A270 / ASME BPE; EN 10204 3.1 MTC standard | O7: VERIFY | P7: =IF($K7="VERIFY","VERIFY",IF(ISNUMBER(SEARCH("semicon",$K7)),"SEMI",IF(ISNUMBER(SEARCH("electronic",$K7)),"SEMI",IF(ISNUMBER(SEARCH("biotech",$K7)),"BIOTECH",IF(ISNUMBER(SEARCH("pharma",$K7)),"PHARMA",IF(ISNUMBER(SEARCH("medical",$K7)),"PHARMA",IF(ISNUMBER(SEARCH("dairy",$K7)),"DAIRY",IF(ISNUMBER(SEARCH("brewery",$K7)),"BREWERY",IF(ISNUMBER(SEARCH("food",$K7)),"FOOD",IF(ISNUMBER(SEARCH("personal care",$K7)),"FOOD",IF(ISNUMBER(SEARCH("chemical",$K7)),"CHEM",IF(ISNUMBER(SEARCH("refining",$K7)),"CHEM",IF(ISNUMBER(SEARCH("petrochem",$K7)),"CHEM",IF(ISNUMBER(SEARCH("fertilis",$K7)),"CHEM",IF(ISNUMBER(SEARCH("water",$K7)),"CHEM","GENERAL"))))))))))))))) -> GENERAL | Q7: =MOD(ROW()-4,8)+1 -> 4 | R7: =MOD(ROW()-4,7)+1 -> 4 | S7: =MOD(ROW()-4,5)+1 -> 4 | T7: =$F7&"-"&(MOD(ROW()-4,6)+1) -> A-4 | U7: ="T"&$Q7&"-M"&$R7&"-H"&$S7&"-F"&$T7&"-"&$P7 -> T4-M4-H4-FA-4-GENERAL | V7: =COUNTIF($U$4:$U$1835,$U7)-1 -> 0 | X7: =IF($W7<>"",$W7,IF($B7="India",LOWER(SUBSTITUTE(SUBSTITUTE($D7," ","-"),".","")),LOWER(SUBSTITUTE(SUBSTITUTE($D7," ","-"),".",""))&"-"&LOWER(SUBSTITUTE($B7," ","-")))) -> ambala | Y7: ="https://steelmanufacturer.in/market-area/electropolished-pipes-manufacturer-in-"&$X7&"/" -> https://steelmanufacturer.in/market-area/electropolished-pipes-manufacturer-in-ambala/ | Z7: =IF($AR7<>"",$AR7,IF(LEN("Electropolished Pipes Manufacturer in "&$E7&CHOOSE($Q7," | Sakshi Forge"," - ASTM A270 & ASME BPE"," | EP Tube Supplier"," - SS 304/316L EP Tube"," | Sanitary Tube Supply"," - Mill Certified Supply"," | ASME BPE SF1-SF4"," - EP Tube Stockist"))<=65,"Electropolished Pipes Manufacturer in "&$E7&CHOOSE($Q7," | Sakshi Forge"," - ASTM A270 & ASME BPE"," | EP Tube Supplier"," - SS 304/316L EP Tube"," | Sanitary Tube Supply"," - Mill Certified Supply"," | ASME BPE SF1-SF4"," - EP Tube Stockist"),"Electropolished Pipes Manufacturer in "&$E7)) -> Electropolished Pipes Manufacturer in Ambala | AA7: =IF(LEN($Z7)>65,"TRIM ("&LEN($Z7)&")",IF(LEN($Z7)<35,"SHORT ("&LEN($Z7)&")","OK ("&LEN($Z7)&")")) -> OK (44) | AB7: =IF($AS7<>"",$AS7,CHOOSE($R7,"EP-finished SS 304/316L pipes & tubes for "&$K7&" plants in "&$E7&". ASTM A270, ASME BPE SF1-SF4, EN 10204 3.1 MTC. PMI tested.","Electropolished tube supply to "&$I7&", "&$E7&". Ra from 0.25 um, SF4 finish, mill test certificate with every lot.","EP stainless tube for "&$K7&" lines in "&$E7&". "&$M7&". ASTM A270 S2, PMI tested, EN 10204 3.1.","Sanitary electropolished pipes in "&$E7&" for "&$K7&" plants. ASME BPE SF1-SF4, orbital-weld ready, 3.1 MTC. Mumbai-made.","Manufacturer of electropolished SS 316L tube serving "&$E7&". "&$M7&". Ra 0.25-0.5 um, EN 10204 3.1 MTC.",IF(LEN("EP tube and pipe for "&$K7&" plants around "&$I7&", "&$E7&". Made at our Mumbai works to ASTM A270 and ASME BPE SF1-SF4, with 3.1 MTC.")<=160,"EP tube and pipe for "&$K7&" plants around "&$I7&", "&$E7&". Made at our Mumbai works to ASTM A270 and ASME BPE SF1-SF4, with 3.1 MTC.","EP tube and pipe for "&$K7&" plants around "&$I7&", "&$E7&". ASTM A270, ASME BPE SF1-SF4, EN 10204 3.1 MTC."),"Electropolished pipes in "&$E7&": 304, 304L, 316 and 316L in SF1-SF4. "&$M7&". Mill certified.")) -> Sanitary electropolished pipes in Ambala for engineering & process plants. ASME BPE SF1-SF4, orbital-weld ready, 3.1 MTC. Mumbai-made. | AC7: =IF($G7="VERIFY","PENDING RESEARCH",IF(LEN($AB7)>160,"TRIM ("&LEN($AB7)&")",IF(LEN($AB7)<110,"SHORT ("&LEN($AB7)&")","OK ("&LEN($AB7)&")"))) -> OK (134) | AD7: ="Electropolished Pipes Manufacturer in "&$E7 -> Electropolished Pipes Manufacturer in Ambala | AE7: =CHOOSE($S7,"Electropolished Pipe & Tube Manufacturing for "&$E7&" - Grades, Finishes & Certification","How We Manufacture Electropolished Tube for "&$E7&" Plants","Electropolished Pipes Manufacturer in "&$E7&" - Our Process & Capability","Manufacturing Electropolished SS Tube for "&$E7&": The Standards We Build To","Electropolished Tube Manufacturing Capability Serving "&$E7) -> Manufacturing Electropolished SS Tube for Ambala: The Standards We Build To | AF7: =CHOOSE($S7,"Electropolished Pipes Supplier in "&$E7&" - Stock Sizes, Lead Time & Delivery","Supplying Electropolished Pipes in "&$E7&": Availability, Sizes & Dispatch","Electropolished Pipes Supplier in "&$E7&" - What We Hold in Stock","Electropolished Pipe Supply Into "&$E7&" - Certification & Transit","Electropolished Pipes Supplier in "&$E7&" - From Order to Delivery") -> Electropolished Pipe Supply Into Ambala - Certification & Transit | AG7: =CHOOSE($S7,"Electropolished Pipes Wholesaler & Stockist in "&$E7&" - Bulk & Project Pricing","Wholesale Electropolished Pipe Supply for "&$E7&" Projects","Bulk & Wholesale Electropolished Pipe Rates for "&$E7&" Buyers","Electropolished Pipes Wholesaler in "&$E7&" - Project Quantities & Terms","Stockist & Wholesale Supply of Electropolished Pipes in "&$E7) -> Electropolished Pipes Wholesaler in Ambala - Project Quantities & Terms | AH7: ="electropolished pipes manufacturer in "&$D7&", electropolished pipes supplier in "&$D7&", electropolished pipes wholesaler in "&$D7&", electropolished tube manufacturer "&$D7&", EP pipe supplier "&$D7&", sanitary tube supplier "&$D7&", ASME BPE tubing "&$D7&", ASTM A270 tube "&$D7&", SS 316L electropolished pipe "&$D7 -> electropolished pipes manufacturer in Ambala, electropolished pipes supplier in Ambala, electropolished pipes wholesaler in Ambala, electropolished tube manufacturer Ambala, EP pipe supplier Ambala, sanitary tube supplier Ambala, ASME BPE tubing Ambala, ASTM A270 tube Ambala, SS 316L electropolished pipe Ambala | AI7: ="Electropolished Pipes Manufacturer & Supplier in "&$E7 -> Electropolished Pipes Manufacturer & Supplier in Ambala | AJ7: ="EP-finished SS 304/316L pipes and tubes for "&$K7&" plants in "&$E7&". ASME BPE SF1-SF4, Ra from 0.25 um, EN 10204 3.1 certificate with every lot." -> EP-finished SS 304/316L pipes and tubes for engineering & process plants in Ambala. ASME BPE SF1-SF4, Ra from 0.25 um, EN 10204 3.1 certificate with every lot. | AK7: ="Electropolished stainless steel pipes supplied by Sakshi Forge to "&$K7&" plants at "&$I7&", "&$E7 -> Electropolished stainless steel pipes supplied by Sakshi Forge to engineering & process plants at Ambala Industrial Area, Ambala | AL7: ="Electropolished SS 316L tube stock for "&$E7&" - Sakshi Forge" -> Electropolished SS 316L tube stock for Ambala - Sakshi Forge | AM7: ="Home > Market Area > "&$B7&" > "&$C7&" > "&$D7 -> Home > Market Area > India > Haryana > Ambala | AN7: =IF($F7="A",1400,IF($F7="B",1000,750)) -> 1400 | AO7: =IF($F7="A",10,IF($F7="B",8,6)) -> 10 | AP7: =IF($F7="A",12,IF($F7="B",8,6)) -> 12 | AQ7: =ROUNDUP((ROW()-3)/60,0) -> 1 | AT7: Not started
A8: CTY-0005 | B8: India | C8: Maharashtra | D8: Ambernath | E8: Ambernath | F8: A | G8: VERIFIED | H8: Ambernath MIDC (Anand Nagar), Additional Ambernath | I8: Ambernath MIDC (Anand Nagar) | J8: Chemicals, pharma intermediates, engineering | K8: chemical | L8: JNPT Nhava Sheva (60 km) | M8: same-day to next-day road from our Mumbai works | N8: PESO / OISD for hazardous service; IBR where applicable | O8: VERIFY | P8: =IF($K8="VERIFY","VERIFY",IF(ISNUMBER(SEARCH("semicon",$K8)),"SEMI",IF(ISNUMBER(SEARCH("electronic",$K8)),"SEMI",IF(ISNUMBER(SEARCH("biotech",$K8)),"BIOTECH",IF(ISNUMBER(SEARCH("pharma",$K8)),"PHARMA",IF(ISNUMBER(SEARCH("medical",$K8)),"PHARMA",IF(ISNUMBER(SEARCH("dairy",$K8)),"DAIRY",IF(ISNUMBER(SEARCH("brewery",$K8)),"BREWERY",IF(ISNUMBER(SEARCH("food",$K8)),"FOOD",IF(ISNUMBER(SEARCH("personal care",$K8)),"FOOD",IF(ISNUMBER(SEARCH("chemical",$K8)),"CHEM",IF(ISNUMBER(SEARCH("refining",$K8)),"CHEM",IF(ISNUMBER(SEARCH("petrochem",$K8)),"CHEM",IF(ISNUMBER(SEARCH("fertilis",$K8)),"CHEM",IF(ISNUMBER(SEARCH("water",$K8)),"CHEM","GENERAL"))))))))))))))) -> CHEM | Q8: =MOD(ROW()-4,8)+1 -> 5 | R8: =MOD(ROW()-4,7)+1 -> 5 | S8: =MOD(ROW()-4,5)+1 -> 5 | T8: =$F8&"-"&(MOD(ROW()-4,6)+1) -> A-5 | U8: ="T"&$Q8&"-M"&$R8&"-H"&$S8&"-F"&$T8&"-"&$P8 -> T5-M5-H5-FA-5-CHEM | V8: =COUNTIF($U$4:$U$1835,$U8)-1 -> 0 | X8: =IF($W8<>"",$W8,IF($B8="India",LOWER(SUBSTITUTE(SUBSTITUTE($D8," ","-"),".","")),LOWER(SUBSTITUTE(SUBSTITUTE($D8," ","-"),".",""))&"-"&LOWER(SUBSTITUTE($B8," ","-")))) -> ambernath | Y8: ="https://steelmanufacturer.in/market-area/electropolished-pipes-manufacturer-in-"&$X8&"/" -> https://steelmanufacturer.in/market-area/electropolished-pipes-manufacturer-in-ambernath/ | Z8: =IF($AR8<>"",$AR8,IF(LEN("Electropolished Pipes Manufacturer in "&$E8&CHOOSE($Q8," | Sakshi Forge"," - ASTM A270 & ASME BPE"," | EP Tube Supplier"," - SS 304/316L EP Tube"," | Sanitary Tube Supply"," - Mill Certified Supply"," | ASME BPE SF1-SF4"," - EP Tube Stockist"))<=65,"Electropolished Pipes Manufacturer in "&$E8&CHOOSE($Q8," | Sakshi Forge"," - ASTM A270 & ASME BPE"," | EP Tube Supplier"," - SS 304/316L EP Tube"," | Sanitary Tube Supply"," - Mill Certified Supply"," | ASME BPE SF1-SF4"," - EP Tube Stockist"),"Electropolished Pipes Manufacturer in "&$E8)) -> Electropolished Pipes Manufacturer in Ambernath | AA8: =IF(LEN($Z8)>65,"TRIM ("&LEN($Z8)&")",IF(LEN($Z8)<35,"SHORT ("&LEN($Z8)&")","OK ("&LEN($Z8)&")")) -> OK (47) | AB8: =IF($AS8<>"",$AS8,CHOOSE($R8,"EP-finished SS 304/316L pipes & tubes for "&$K8&" plants in "&$E8&". ASTM A270, ASME BPE SF1-SF4, EN 10204 3.1 MTC. PMI tested.","Electropolished tube supply to "&$I8&", "&$E8&". Ra from 0.25 um, SF4 finish, mill test certificate with every lot.","EP stainless tube for "&$K8&" lines in "&$E8&". "&$M8&". ASTM A270 S2, PMI tested, EN 10204 3.1.","Sanitary electropolished pipes in "&$E8&" for "&$K8&" plants. ASME BPE SF1-SF4, orbital-weld ready, 3.1 MTC. Mumbai-made.","Manufacturer of electropolished SS 316L tube serving "&$E8&". "&$M8&". Ra 0.25-0.5 um, EN 10204 3.1 MTC.",IF(LEN("EP tube and pipe for "&$K8&" plants around "&$I8&", "&$E8&". Made at our Mumbai works to ASTM A270 and ASME BPE SF1-SF4, with 3.1 MTC.")<=160,"EP tube and pipe for "&$K8&" plants around "&$I8&", "&$E8&". Made at our Mumbai works to ASTM A270 and ASME BPE SF1-SF4, with 3.1 MTC.","EP tube and pipe for "&$K8&" plants around "&$I8&", "&$E8&". ASTM A270, ASME BPE SF1-SF4, EN 10204 3.1 MTC."),"Electropolished pipes in "&$E8&": 304, 304L, 316 and 316L in SF1-SF4. "&$M8&". Mill certified.")) -> Manufacturer of electropolished SS 316L tube serving Ambernath. same-day to next-day road from our Mumbai works. Ra 0.25-0.5 um, EN 10204 3.1 MTC. | AC8: =IF($G8="VERIFY","PENDING RESEARCH",IF(LEN($AB8)>160,"TRIM ("&LEN($AB8)&")",IF(LEN($AB8)<110,"SHORT ("&LEN($AB8)&")","OK ("&LEN($AB8)&")"))) -> OK (146) | AD8: ="Electropolished Pipes Manufacturer in "&$E8 -> Electropolished Pipes Manufacturer in Ambernath | AE8: =CHOOSE($S8,"Electropolished Pipe & Tube Manufacturing for "&$E8&" - Grades, Finishes & Certification","How We Manufacture Electropolished Tube for "&$E8&" Plants","Electropolished Pipes Manufacturer in "&$E8&" - Our Process & Capability","Manufacturing Electropolished SS Tube for "&$E8&": The Standards We Build To","Electropolished Tube Manufacturing Capability Serving "&$E8) -> Electropolished Tube Manufacturing Capability Serving Ambernath | AF8: =CHOOSE($S8,"Electropolished Pipes Supplier in "&$E8&" - Stock Sizes, Lead Time & Delivery","Supplying Electropolished Pipes in "&$E8&": Availability, Sizes & Dispatch","Electropolished Pipes Supplier in "&$E8&" - What We Hold in Stock","Electropolished Pipe Supply Into "&$E8&" - Certification & Transit","Electropolished Pipes Supplier in "&$E8&" - From Order to Delivery") -> Electropolished Pipes Supplier in Ambernath - From Order to Delivery | AG8: =CHOOSE($S8,"Electropolished Pipes Wholesaler & Stockist in "&$E8&" - Bulk & Project Pricing","Wholesale Electropolished Pipe Supply for "&$E8&" Projects","Bulk & Wholesale Electropolished Pipe Rates for "&$E8&" Buyers","Electropolished Pipes Wholesaler in "&$E8&" - Project Quantities & Terms","Stockist & Wholesale Supply of Electropolished Pipes in "&$E8) -> Stockist & Wholesale Supply of Electropolished Pipes in Ambernath | AH8: ="electropolished pipes manufacturer in "&$D8&", electropolished pipes supplier in "&$D8&", electropolished pipes wholesaler in "&$D8&", electropolished tube manufacturer "&$D8&", EP pipe supplier "&$D8&", sanitary tube supplier "&$D8&", ASME BPE tubing "&$D8&", ASTM A270 tube "&$D8&", SS 316L electropolished pipe "&$D8 -> electropolished pipes manufacturer in Ambernath, electropolished pipes supplier in Ambernath, electropolished pipes wholesaler in Ambernath, electropolished tube manufacturer Ambernath, EP pipe supplier Ambernath, sanitary tube supplier Ambernath, ASME BPE tubing Ambernath, ASTM A270 tube Ambernath, SS 316L electropolished pipe Ambernath | AI8: ="Electropolished Pipes Manufacturer & Supplier in "&$E8 -> Electropolished Pipes Manufacturer & Supplier in Ambernath | AJ8: ="EP-finished SS 304/316L pipes and tubes for "&$K8&" plants in "&$E8&". ASME BPE SF1-SF4, Ra from 0.25 um, EN 10204 3.1 certificate with every lot." -> EP-finished SS 304/316L pipes and tubes for chemical plants in Ambernath. ASME BPE SF1-SF4, Ra from 0.25 um, EN 10204 3.1 certificate with every lot. | AK8: ="Electropolished stainless steel pipes supplied by Sakshi Forge to "&$K8&" plants at "&$I8&", "&$E8 -> Electropolished stainless steel pipes supplied by Sakshi Forge to chemical plants at Ambernath MIDC (Anand Nagar), Ambernath | AL8: ="Electropolished SS 316L tube stock for "&$E8&" - Sakshi Forge" -> Electropolished SS 316L tube stock for Ambernath - Sakshi Forge | AM8: ="Home > Market Area > "&$B8&" > "&$C8&" > "&$D8 -> Home > Market Area > India > Maharashtra > Ambernath | AN8: =IF($F8="A",1400,IF($F8="B",1000,750)) -> 1400 | AO8: =IF($F8="A",10,IF($F8="B",8,6)) -> 10 | AP8: =IF($F8="A",12,IF($F8="B",8,6)) -> 12 | AQ8: =ROUNDUP((ROW()-3)/60,0) -> 1 | AT8: Not started
A9: CTY-0006 | B9: India | C9: Punjab | D9: Amritsar | E9: Amritsar | F9: A | G9: VERIFIED | H9: Focal Point Amritsar, Mehta Road Estate | I9: Focal Point Amritsar | J9: Food processing, textiles, engineering | K9: food processing | L9: ICD Ludhiana (140 km) | M9: 1-2 day road transit from our Mumbai works | N9: FSSAI licensing; 3-A Sanitary Standards on product-contact lines | O9: VERIFY | P9: =IF($K9="VERIFY","VERIFY",IF(ISNUMBER(SEARCH("semicon",$K9)),"SEMI",IF(ISNUMBER(SEARCH("electronic",$K9)),"SEMI",IF(ISNUMBER(SEARCH("biotech",$K9)),"BIOTECH",IF(ISNUMBER(SEARCH("pharma",$K9)),"PHARMA",IF(ISNUMBER(SEARCH("medical",$K9)),"PHARMA",IF(ISNUMBER(SEARCH("dairy",$K9)),"DAIRY",IF(ISNUMBER(SEARCH("brewery",$K9)),"BREWERY",IF(ISNUMBER(SEARCH("food",$K9)),"FOOD",IF(ISNUMBER(SEARCH("personal care",$K9)),"FOOD",IF(ISNUMBER(SEARCH("chemical",$K9)),"CHEM",IF(ISNUMBER(SEARCH("refining",$K9)),"CHEM",IF(ISNUMBER(SEARCH("petrochem",$K9)),"CHEM",IF(ISNUMBER(SEARCH("fertilis",$K9)),"CHEM",IF(ISNUMBER(SEARCH("water",$K9)),"CHEM","GENERAL"))))))))))))))) -> FOOD | Q9: =MOD(ROW()-4,8)+1 -> 6 | R9: =MOD(ROW()-4,7)+1 -> 6 | S9: =MOD(ROW()-4,5)+1 -> 1 | T9: =$F9&"-"&(MOD(ROW()-4,6)+1) -> A-6 | U9: ="T"&$Q9&"-M"&$R9&"-H"&$S9&"-F"&$T9&"-"&$P9 -> T6-M6-H1-FA-6-FOOD | V9: =COUNTIF($U$4:$U$1835,$U9)-1 -> 0 | X9: =IF($W9<>"",$W9,IF($B9="India",LOWER(SUBSTITUTE(SUBSTITUTE($D9," ","-"),".","")),LOWER(SUBSTITUTE(SUBSTITUTE($D9," ","-"),".",""))&"-"&LOWER(SUBSTITUTE($B9," ","-")))) -> amritsar | Y9: ="https://steelmanufacturer.in/market-area/electropolished-pipes-manufacturer-in-"&$X9&"/" -> https://steelmanufacturer.in/market-area/electropolished-pipes-manufacturer-in-amritsar/ | Z9: =IF($AR9<>"",$AR9,IF(LEN("Electropolished Pipes Manufacturer in "&$E9&CHOOSE($Q9," | Sakshi Forge"," - ASTM A270 & ASME BPE"," | EP Tube Supplier"," - SS 304/316L EP Tube"," | Sanitary Tube Supply"," - Mill Certified Supply"," | ASME BPE SF1-SF4"," - EP Tube Stockist"))<=65,"Electropolished Pipes Manufacturer in "&$E9&CHOOSE($Q9," | Sakshi Forge"," - ASTM A270 & ASME BPE"," | EP Tube Supplier"," - SS 304/316L EP Tube"," | Sanitary Tube Supply"," - Mill Certified Supply"," | ASME BPE SF1-SF4"," - EP Tube Stockist"),"Electropolished Pipes Manufacturer in "&$E9)) -> Electropolished Pipes Manufacturer in Amritsar | AA9: =IF(LEN($Z9)>65,"TRIM ("&LEN($Z9)&")",IF(LEN($Z9)<35,"SHORT ("&LEN($Z9)&")","OK ("&LEN($Z9)&")")) -> OK (46) | AB9: =IF($AS9<>"",$AS9,CHOOSE($R9,"EP-finished SS 304/316L pipes & tubes for "&$K9&" plants in "&$E9&". ASTM A270, ASME BPE SF1-SF4, EN 10204 3.1 MTC. PMI tested.","Electropolished tube supply to "&$I9&", "&$E9&". Ra from 0.25 um, SF4 finish, mill test certificate with every lot.","EP stainless tube for "&$K9&" lines in "&$E9&". "&$M9&". ASTM A270 S2, PMI tested, EN 10204 3.1.","Sanitary electropolished pipes in "&$E9&" for "&$K9&" plants. ASME BPE SF1-SF4, orbital-weld ready, 3.1 MTC. Mumbai-made.","Manufacturer of electropolished SS 316L tube serving "&$E9&". "&$M9&". Ra 0.25-0.5 um, EN 10204 3.1 MTC.",IF(LEN("EP tube and pipe for "&$K9&" plants around "&$I9&", "&$E9&". Made at our Mumbai works to ASTM A270 and ASME BPE SF1-SF4, with 3.1 MTC.")<=160,"EP tube and pipe for "&$K9&" plants around "&$I9&", "&$E9&". Made at our Mumbai works to ASTM A270 and ASME BPE SF1-SF4, with 3.1 MTC.","EP tube and pipe for "&$K9&" plants around "&$I9&", "&$E9&". ASTM A270, ASME BPE SF1-SF4, EN 10204 3.1 MTC."),"Electropolished pipes in "&$E9&": 304, 304L, 316 and 316L in SF1-SF4. "&$M9&". Mill certified.")) -> EP tube and pipe for food processing plants around Focal Point Amritsar, Amritsar. Made at our Mumbai works to ASTM A270 and ASME BPE SF1-SF4, with 3.1 MTC. | AC9: =IF($G9="VERIFY","PENDING RESEARCH",IF(LEN($AB9)>160,"TRIM ("&LEN($AB9)&")",IF(LEN($AB9)<110,"SHORT ("&LEN($AB9)&")","OK ("&LEN($AB9)&")"))) -> OK (156) | AD9: ="Electropolished Pipes Manufacturer in "&$E9 -> Electropolished Pipes Manufacturer in Amritsar | AE9: =CHOOSE($S9,"Electropolished Pipe & Tube Manufacturing for "&$E9&" - Grades, Finishes & Certification","How We Manufacture Electropolished Tube for "&$E9&" Plants","Electropolished Pipes Manufacturer in "&$E9&" - Our Process & Capability","Manufacturing Electropolished SS Tube for "&$E9&": The Standards We Build To","Electropolished Tube Manufacturing Capability Serving "&$E9) -> Electropolished Pipe & Tube Manufacturing for Amritsar - Grades, Finishes & Certification | AF9: =CHOOSE($S9,"Electropolished Pipes Supplier in "&$E9&" - Stock Sizes, Lead Time & Delivery","Supplying Electropolished Pipes in "&$E9&": Availability, Sizes & Dispatch","Electropolished Pipes Supplier in "&$E9&" - What We Hold in Stock","Electropolished Pipe Supply Into "&$E9&" - Certification & Transit","Electropolished Pipes Supplier in "&$E9&" - From Order to Delivery") -> Electropolished Pipes Supplier in Amritsar - Stock Sizes, Lead Time & Delivery | AG9: =CHOOSE($S9,"Electropolished Pipes Wholesaler & Stockist in "&$E9&" - Bulk & Project Pricing","Wholesale Electropolished Pipe Supply for "&$E9&" Projects","Bulk & Wholesale Electropolished Pipe Rates for "&$E9&" Buyers","Electropolished Pipes Wholesaler in "&$E9&" - Project Quantities & Terms","Stockist & Wholesale Supply of Electropolished Pipes in "&$E9) -> Electropolished Pipes Wholesaler & Stockist in Amritsar - Bulk & Project Pricing | AH9: ="electropolished pipes manufacturer in "&$D9&", electropolished pipes supplier in "&$D9&", electropolished pipes wholesaler in "&$D9&", electropolished tube manufacturer "&$D9&", EP pipe supplier "&$D9&", sanitary tube supplier "&$D9&", ASME BPE tubing "&$D9&", ASTM A270 tube "&$D9&", SS 316L electropolished pipe "&$D9 -> electropolished pipes manufacturer in Amritsar, electropolished pipes supplier in Amritsar, electropolished pipes wholesaler in Amritsar, electropolished tube manufacturer Amritsar, EP pipe supplier Amritsar, sanitary tube supplier Amritsar, ASME BPE tubing Amritsar, ASTM A270 tube Amritsar, SS 316L electropolished pipe Amritsar | AI9: ="Electropolished Pipes Manufacturer & Supplier in "&$E9 -> Electropolished Pipes Manufacturer & Supplier in Amritsar | AJ9: ="EP-finished SS 304/316L pipes and tubes for "&$K9&" plants in "&$E9&". ASME BPE SF1-SF4, Ra from 0.25 um, EN 10204 3.1 certificate with every lot." -> EP-finished SS 304/316L pipes and tubes for food processing plants in Amritsar. ASME BPE SF1-SF4, Ra from 0.25 um, EN 10204 3.1 certificate with every lot. | AK9: ="Electropolished stainless steel pipes supplied by Sakshi Forge to "&$K9&" plants at "&$I9&", "&$E9 -> Electropolished stainless steel pipes supplied by Sakshi Forge to food processing plants at Focal Point Amritsar, Amritsar | AL9: ="Electropolished SS 316L tube stock for "&$E9&" - Sakshi Forge" -> Electropolished SS 316L tube stock for Amritsar - Sakshi Forge | AM9: ="Home > Market Area > "&$B9&" > "&$C9&" > "&$D9 -> Home > Market Area > India > Punjab > Amritsar | AN9: =IF($F9="A",1400,IF($F9="B",1000,750)) -> 1400 | AO9: =IF($F9="A",10,IF($F9="B",8,6)) -> 10 | AP9: =IF($F9="A",12,IF($F9="B",8,6)) -> 12 | AQ9: =ROUNDUP((ROW()-3)/60,0) -> 1 | AT9: Not started
