Workbook

Sheet 00 README
A1: SAKSHI FORGE — ELECTROPOLISHED PIPE SEO BUILD SPEC
A2: Developer handover pack · steelmanufacturer.in · 106 pages · organic / SEO only
A4: SECTION | B4: WHAT IT CONTAINS | C4: WHO ACTS ON IT | D4: DO THIS FIRST?
A5: 01 Dashboard | B5: Live counts of pages by phase, type and build status. Updates automatically as the Status columns in 02 are filled in. | C5: Akshat (tracking) | D5: No
A6: 02 Page Master | B6: THE BUILD LIST. Every URL, H1, title tag, meta description, target keyword, word count, schema and internal links. One row = one page to build. | C6: Developer + content writer | D6: YES — this is the core sheet
A7: 03 Keyword Bank | B7: All 55 seed keywords plus city and industry expansions, each classified by intent and mapped to exactly one URL so two pages never chase the same term. | C7: Content writer | D7: Read before writing
A8: 04 Page Templates | B8: The H1/H2/H3 skeleton for each page type, plus the mandatory on-page blocks (spec table, FAQ, CTA). Follow these so every page is consistent. | C8: Content writer + developer | D8: Read before writing
A9: 05 Internal Linking | B9: The silo rules: what links to what, anchor text patterns, breadcrumb structure. Getting this right is most of the ranking benefit. | C9: Developer | D9: YES
A10: 06 Schema Markup | B10: Copy-paste JSON-LD blocks for each schema type, with the fields to swap. Google rich results depend on these being valid. | C10: Developer | D10: YES
A11: 07 Technical SEO | B11: The non-negotiable technical checklist — indexation, sitemap, robots.txt, canonicals, speed, mobile, image handling. | C11: Developer | D11: YES — item 1 is urgent
A12: 08 Build Phases | B12: Sequenced delivery plan. Phase 1 first, and do NOT start Phase 4 until Phase 1-3 pages are indexed and ranking. | C12: Both | D12: YES
A13: 09 City & Industry Data | B13: Reference table of every target city, its industrial areas and sectors — the raw material for writing unique local content. | C13: Content writer | D13: Read before writing city pages
A14: 10 Competitor Benchmark | B14: What cerapuresteel.com and mahadevdairypharmafitting.com do, and the specific gaps this build is designed to exploit. | C14: Both | D14: Context
A16: HOW TO USE THIS WORKBOOK
A17: 1. Developer works top-to-bottom through sheet 07 Technical SEO. Nothing on this site can rank until it is crawlable and indexed.
A18: 2. Filter sheet 02 Page Master by Phase = 1. Build only those 25 pages first. Copy the Title Tag and Meta Description columns literally — they are already length-checked.
A19: 3. For each page, open sheet 04 Page Templates, find the matching Page Type, and follow its heading skeleton and mandatory blocks.
A20: 4. Apply the JSON-LD from sheet 06 that matches the Schema column for that page. Validate every page at search.google.com/test/rich-results before marking it done.
A21: 5. Wire internal links exactly as sheet 05 specifies. Use the anchor text given — not 'click here', not the bare URL.
A22: 6. Update the Dev Status and Content Status columns in sheet 02 as you go. Sheet 01 Dashboard totals update by themselves.
A23: 7. Submit each finished batch in Google Search Console and confirm indexation before starting the next phase.
A25: COLOUR LEGEND
B26: Amber fill = a cell YOU must fill in or decide. Nothing amber should ship as-is.
B27: Green fill = ready to use exactly as written. Copy it literally.
B28: Red fill = warning / risk. Read the note before acting.
B29: Blue fill = reference data, not an instruction.
A32: CRITICAL WARNING — READ BEFORE BUILDING PHASE 4
A33: Phase 4 contains 45 pages, of which 27 are City x Product and Industry x City combinations. These only work if each one carries genuinely different content — real local industrial areas, real dispatch lead times, real stock positions. If they are spun from a template with the city name swapped, Google treats them as scaled content abuse and the penalty lands on the WHOLE domain, not just those pages. Both competitors analysed are carrying this risk already. If you cannot write 27 genuinely distinct pages, build 10 good ones and delete the rest from the plan.

Sheet 01 Dashboard
A1: BUILD DASHBOARD
A2: All figures are live formulas reading sheet '02 Page Master'. Do not overwrite them.
A4: PAGES BY PHASE
A5: Phase | B5: Pages | C5: Not started | D5: In progress | E5: Live | F5: % Complete
A6: Phase 1 — Foundation | B6: =COUNTIF('02 Page Master'!$C$4:$C$109,1) -> 18 | C6: =COUNTIFS('02 Page Master'!$C$4:$C$109,1,'02 Page Master'!$U$4:$U$109,"Not started") -> 18 | D6: =COUNTIFS('02 Page Master'!$C$4:$C$109,1,'02 Page Master'!$U$4:$U$109,"In progress") -> 0 | E6: =COUNTIFS('02 Page Master'!$C$4:$C$109,1,'02 Page Master'!$U$4:$U$109,"Live") -> 0 | F6: =IFERROR(E6/B6,0) -> 0
A7: Phase 2 — Depth | B7: =COUNTIF('02 Page Master'!$C$4:$C$109,2) -> 22 | C7: =COUNTIFS('02 Page Master'!$C$4:$C$109,2,'02 Page Master'!$U$4:$U$109,"Not started") -> 22 | D7: =COUNTIFS('02 Page Master'!$C$4:$C$109,2,'02 Page Master'!$U$4:$U$109,"In progress") -> 0 | E7: =COUNTIFS('02 Page Master'!$C$4:$C$109,2,'02 Page Master'!$U$4:$U$109,"Live") -> 0 | F7: =IFERROR(E7/B7,0) -> 0
A8: Phase 3 — Reach | B8: =COUNTIF('02 Page Master'!$C$4:$C$109,3) -> 21 | C8: =COUNTIFS('02 Page Master'!$C$4:$C$109,3,'02 Page Master'!$U$4:$U$109,"Not started") -> 21 | D8: =COUNTIFS('02 Page Master'!$C$4:$C$109,3,'02 Page Master'!$U$4:$U$109,"In progress") -> 0 | E8: =COUNTIFS('02 Page Master'!$C$4:$C$109,3,'02 Page Master'!$U$4:$U$109,"Live") -> 0 | F8: =IFERROR(E8/B8,0) -> 0
A9: Phase 4 — Expansion (gated) | B9: =COUNTIF('02 Page Master'!$C$4:$C$109,4) -> 45 | C9: =COUNTIFS('02 Page Master'!$C$4:$C$109,4,'02 Page Master'!$U$4:$U$109,"Not started") -> 45 | D9: =COUNTIFS('02 Page Master'!$C$4:$C$109,4,'02 Page Master'!$U$4:$U$109,"In progress") -> 0 | E9: =COUNTIFS('02 Page Master'!$C$4:$C$109,4,'02 Page Master'!$U$4:$U$109,"Live") -> 0 | F9: =IFERROR(E9/B9,0) -> 0
A10: TOTAL | B10: =SUM(B6:B9) -> 106 | C10: =SUM(C6:C9) -> 106 | D10: =SUM(D6:D9) -> 0 | E10: =SUM(E6:E9) -> 0 | F10: =IFERROR(E10/B10,0) -> 0
A13: PAGES BY TYPE
A14: Page type | B14: Pages | C14: Live | D14: % Complete
A15: Blog | B15: =COUNTIF('02 Page Master'!$D$4:$D$109,A15) -> 12 | C15: =COUNTIFS('02 Page Master'!$D$4:$D$109,A15,'02 Page Master'!$U$4:$U$109,"Live") -> 0 | D15: =IFERROR(C15/B15,0) -> 0
A16: Category Hub | B16: =COUNTIF('02 Page Master'!$D$4:$D$109,A16) -> 6 | C16: =COUNTIFS('02 Page Master'!$D$4:$D$109,A16,'02 Page Master'!$U$4:$U$109,"Live") -> 0 | D16: =IFERROR(C16/B16,0) -> 0
A17: City | B17: =COUNTIF('02 Page Master'!$D$4:$D$109,A17) -> 14 | C17: =COUNTIFS('02 Page Master'!$D$4:$D$109,A17,'02 Page Master'!$U$4:$U$109,"Live") -> 0 | D17: =IFERROR(C17/B17,0) -> 0
A18: City x Product | B18: =COUNTIF('02 Page Master'!$D$4:$D$109,A18) -> 15 | C18: =COUNTIFS('02 Page Master'!$D$4:$D$109,A18,'02 Page Master'!$U$4:$U$109,"Live") -> 0 | D18: =IFERROR(C18/B18,0) -> 0
A19: Homepage | B19: =COUNTIF('02 Page Master'!$D$4:$D$109,A19) -> 1 | C19: =COUNTIFS('02 Page Master'!$D$4:$D$109,A19,'02 Page Master'!$U$4:$U$109,"Live") -> 0 | D19: =IFERROR(C19/B19,0) -> 0
A20: Industry | B20: =COUNTIF('02 Page Master'!$D$4:$D$109,A20) -> 12 | C20: =COUNTIFS('02 Page Master'!$D$4:$D$109,A20,'02 Page Master'!$U$4:$U$109,"Live") -> 0 | D20: =IFERROR(C20/B20,0) -> 0
A21: Industry x City | B21: =COUNTIF('02 Page Master'!$D$4:$D$109,A21) -> 12 | C21: =COUNTIFS('02 Page Master'!$D$4:$D$109,A21,'02 Page Master'!$U$4:$U$109,"Live") -> 0 | D21: =IFERROR(C21/B21,0) -> 0
A22: Product (Money) | B22: =COUNTIF('02 Page Master'!$D$4:$D$109,A22) -> 12 | C22: =COUNTIFS('02 Page Master'!$D$4:$D$109,A22,'02 Page Master'!$U$4:$U$109,"Live") -> 0 | D22: =IFERROR(C22/B22,0) -> 0
A23: Resource/chart | B23: =COUNTIF('02 Page Master'!$D$4:$D$109,A23) -> 2 | C23: =COUNTIFS('02 Page Master'!$D$4:$D$109,A23,'02 Page Master'!$U$4:$U$109,"Live") -> 0 | D23: =IFERROR(C23/B23,0) -> 0
A24: Resource/commercial | B24: =COUNTIF('02 Page Master'!$D$4:$D$109,A24) -> 1 | C24: =COUNTIFS('02 Page Master'!$D$4:$D$109,A24,'02 Page Master'!$U$4:$U$109,"Live") -> 0 | D24: =IFERROR(C24/B24,0) -> 0
A25: Resource/comparison | B25: =COUNTIF('02 Page Master'!$D$4:$D$109,A25) -> 3 | C25: =COUNTIFS('02 Page Master'!$D$4:$D$109,A25,'02 Page Master'!$U$4:$U$109,"Live") -> 0 | D25: =IFERROR(C25/B25,0) -> 0
A26: Resource/leadmagnet | B26: =COUNTIF('02 Page Master'!$D$4:$D$109,A26) -> 1 | C26: =COUNTIFS('02 Page Master'!$D$4:$D$109,A26,'02 Page Master'!$U$4:$U$109,"Live") -> 0 | D26: =IFERROR(C26/B26,0) -> 0
... A30: Trust/Conversion | B30: =COUNTIF('02 Page Master'!$D$4:$D$109,A30) -> 7 | C30: =COUNTIFS('02 Page Master'!$D$4:$D$109,A30,'02 Page Master'!$U$4:$U$109,"Live") -> 0 | D30: =IFERROR(C30/B30,0) -> 0
A33: QUALITY GATES
A34: Check | B34: Count | C34: Should be | D34: Status
A35: Title tags over 60 characters | B35: =COUNTIF('02 Page Master'!$H$4:$H$109,">60") -> 0 | C35: 0 | D35: =IF(B35=0,"PASS","FIX") -> PASS
A36: Meta descriptions over 158 characters | B36: =COUNTIF('02 Page Master'!$J$4:$J$109,">158") -> 0 | C36: 0 | D36: =IF(B36=0,"PASS","FIX") -> PASS
A37: Meta descriptions under 110 characters | B37: =COUNTIF('02 Page Master'!$J$4:$J$109,"<110") -> 0 | C37: 0 | D37: =IF(B37=0,"PASS","FIX") -> PASS
A38: Pages with no schema assigned | B38: =COUNTIF('02 Page Master'!$N$4:$N$109,"") -> 0 | C38: 0 | D38: =IF(B38=0,"PASS","FIX") -> PASS
A39: Pages still awaiting content | B39: =COUNTIF('02 Page Master'!$V$4:$V$109,"Not started") -> 106 | C39: 0 at launch | D39: =IF(B39=0,"PASS","IN PROGRESS") -> IN PROGRESS
A42: Assumption: 'Live' means published, indexed and confirmed in Google Search Console — not merely uploaded to the server.

Sheet 02 Page Master
A1: PAGE MASTER — THE BUILD LIST
A2: One row = one page. Columns G and I are ready to copy literally. Amber columns are yours to update. Filter by Phase to work in sequence.
A3: ID | B3: Priority | C3: Phase | D3: Page Type | E3: URL (full path) | F3: H1 (on-page heading) | G3: Title Tag <title> | H3: Title len | I3: Meta Description | J3: Meta len | K3: Primary Keyword | L3: Secondary Keywords | M3: Word Count Target | N3: Schema Types | O3: Parent (breadcrumb) | P3: Internal Links OUT | Q3: Conversion Element (CTA) | R3: Image alt / filename base | S3: Build Notes for Developer | U3: Dev Status | V3: Content Status | W3: Date Live | X3: GSC Indexed?
A4: SF-001 | B4: P1 | C4: 1 | D4: Homepage | E4: / | F4: Electropolished Pipes & Tubes Manufacturer in India | G4: Electropolished Pipe Manufacturer India | Sakshi Forge | H4: =LEN(G4) -> 54 | I4: ISO 9001:2015 certified electropolished pipe & tube manufacturer in Mumbai. SS 316L/304L EP pipes, Ra 0.38 um, ASTM A270, EN 10204 3.1 MTC. Get a quote in. | J4: =LEN(I4) -> 155 | K4: electropolished pipe manufacturer india | L4: electropolished pipes | EP pipes | electropolished stainless steel pipes | SS EP pipes | M4: 1200 | N4: Organization; WebSite; SiteNavigationElement; BreadcrumbList | O4: - | P4: All 12 product pages, top 5 industry pages, top 5 city pages, /request-a-quote/ | Q4: Sticky RFQ bar + WhatsApp + phone; hero quote form (4 fields) | R4: sakshi-forge-electropolished-pipe-manufacturer-india | S4: Hero must state: EP capability, Ra value, grades, standards, MOQ, delivery. Add trust strip (ISO logo, MTC, PMI) above the fold. | U4: Not started | V4: Not started | X4: No
A5: SF-002 | B5: P1 | C5: 1 | D5: Category Hub | E5: /products/ | F5: Electropolished Pipes, Tubes & Fittings | G5: EP Pipes, Tubes & Fittings — Product Range | Sakshi Forge | H5: =LEN(G5) -> 57 | I5: Full range of electropolished stainless steel pipes, tubes and fittings in SS 316L and 304L. Seamless, ERW, ID-EP, sanitary and UHP grades. Request a quote. | J5: =LEN(I5) -> 156 | K5: electropolished pipes and fittings | L5: EP pipes | EP tubes | electropolished pipe fittings | M5: 900 | N5: CollectionPage; BreadcrumbList | O5: / | P5: All 12 product pages | Q5: Inline RFQ form | R5: electropolished-pipe-product-range | S5: Card grid, one card per product page. Each card = image + 2-line spec + 'Get Quote'. | U5: Not started | V5: Not started | X5: No
A6: SF-003 | B6: P1 | C6: 1 | D6: Product (Money) | E6: /electropolished-pipes/ | F6: Electropolished Pipes Manufacturer & Supplier | G6: Electropolished Pipes Manufacturer & Supplier | India | H6: =LEN(G6) -> 53 | I6: Electropolished SS pipes in 304L & 316L, Ra down to 0.38 um (15 uin). ASTM A270/A312, ASME BPE SF4, EN 10204 3.1 MTC. Mumbai manufacturer — quote in 24 hrs. | J6: =LEN(I6) -> 156 | K6: electropolished pipes | L6: electropolished ss pipes | electropolished stainless steel pipes | EP pipes | SS EP pipes | stainless steel EP pipes | M6: 1500 | N6: Product; BreadcrumbList; FAQPage; Organization | O6: /products/ | P6: /asme-bpe-electropolished-tubes/, /astm-a270-electropolished-tubes/, top 3 industry pages, /request-a-quote/ | Q6: Spec-table + inline RFQ (grade, OD, WT, qty, Ra) + WhatsApp | R6: electropolished-pipes-sakshi-forge | S6: MUST include: spec table (OD/WT/length/Ra), chemical composition table, standards list, 6-8 FAQ block, 3 real photos of stock. | U6: Not started | V6: Not started | X6: No
A7: SF-004 | B7: P1 | C7: 1 | D7: Product (Money) | E7: /electropolished-tubes/ | F7: Electropolished Tubes Manufacturer & Supplier | G7: Electropolished Tubes Manufacturer & Supplier India | H7: =LEN(G7) -> 51 | I7: SS electropolished tubes for pharma, dairy & biotech. ASTM A270 sanitary tubing, ASME BPE SF4 finish, ID Ra 0.38 um. ISO 9001:2015 manufacturer. Get. | J7: =LEN(I7) -> 149 | K7: electropolished tubes | L7: SS electropolished tubes | EP tubes | electropolished tube supplier | M7: 1500 | N7: Product; BreadcrumbList; FAQPage; Organization | O7: /products/ | P7: /asme-bpe-electropolished-tubes/, /astm-a270-electropolished-tubes/, top 3 industry pages, /request-a-quote/ | Q7: Spec-table + inline RFQ (grade, OD, WT, qty, Ra) + WhatsApp | R7: electropolished-tubes-sakshi-forge | S7: MUST include: spec table (OD/WT/length/Ra), chemical composition table, standards list, 6-8 FAQ block, 3 real photos of stock. | U7: Not started | V7: Not started | X7: No
A8: SF-005 | B8: P1 | C8: 1 | D8: Product (Money) | E8: /ss-316l-electropolished-pipes/ | F8: SS 316L Electropolished Pipes Manufacturer & Supplier | G8: SS 316L Electropolished Pipes | 316L EP Pipe Supplier | H8: =LEN(G8) -> 53 | I8: SS 316L electropolished pipes & tubes with ID Ra 0.38 um, ASME BPE SF4. For WFI, CIP/SIP, API and bioprocess lines. EN 10204 3.1 MTC + PMI. Request a quote. | J8: =LEN(I8) -> 156 | K8: ss 316l electropolished pipes | L8: SS 316L EP pipes | 316L EP tubes | 316L electropolished tubing | M8: 1500 | N8: Product; BreadcrumbList; FAQPage; Organization | O8: /products/ | P8: /asme-bpe-electropolished-tubes/, /astm-a270-electropolished-tubes/, top 3 industry pages, /request-a-quote/ | Q8: Spec-table + inline RFQ (grade, OD, WT, qty, Ra) + WhatsApp | R8: ss-316l-electropolished-pipes-sakshi-forge | S8: MUST include: spec table (OD/WT/length/Ra), chemical composition table, standards list, 6-8 FAQ block, 3 real photos of stock. | U8: Not started | V8: Not started | X8: No
A9: SF-006 | B9: P1 | C9: 1 | D9: Product (Money) | E9: /ss-304l-electropolished-pipes/ | F9: SS 304L Electropolished Pipes Manufacturer & Supplier | G9: SS 304L Electropolished Pipes | 304L EP Pipe Supplier | H9: =LEN(G9) -> 53 | I9: SS 304L electropolished pipes for dairy, food and beverage process lines. Sanitary Ra finish, ASTM A270 compliant, MTC supplied. Mumbai manufacturer — get. | J9: =LEN(I9) -> 155 | K9: ss 304l electropolished pipes | L9: 304L EP tubes | 304L electropolished tubing | SS 304L EP pipes | M9: 1500 | N9: Product; BreadcrumbList; FAQPage; Organization | O9: /products/ | P9: /asme-bpe-electropolished-tubes/, /astm-a270-electropolished-tubes/, top 3 industry pages, /request-a-quote/ | Q9: Spec-table + inline RFQ (grade, OD, WT, qty, Ra) + WhatsApp | R9: ss-304l-electropolished-pipes-sakshi-forge | S9: MUST include: spec table (OD/WT/length/Ra), chemical composition table, standards list, 6-8 FAQ block, 3 real photos of stock. | U9: Not started | V9: Not started | X9: No
A10: SF-007 | B10: P1 | C10: 1 | D10: Product (Money) | E10: /electropolished-seamless-pipes/ | F10: Electropolished Seamless Pipes Manufacturer & Supplier | G10: Electropolished Seamless Pipes Manufacturer India | H10: =LEN(G10) -> 49 | I10: Seamless electropolished stainless steel pipes in 316L/304L. No weld seam, uniform ID finish for high-purity and UHP service. ASTM A213/A269. Request. | J10: =LEN(I10) -> 150 | K10: electropolished seamless pipes | L10: EP seamless pipes | seamless electropolished tubing | M10: 1500 | N10: Product; BreadcrumbList; FAQPage; Organization | O10: /products/ | P10: /asme-bpe-electropolished-tubes/, /astm-a270-electropolished-tubes/, top 3 industry pages, /request-a-quote/ | Q10: Spec-table + inline RFQ (grade, OD, WT, qty, Ra) + WhatsApp | R10: electropolished-seamless-pipes-sakshi-forge | S10: MUST include: spec table (OD/WT/length/Ra), chemical composition table, standards list, 6-8 FAQ block, 3 real photos of stock. | U10: Not started | V10: Not started | X10: No
A11: SF-008 | B11: P1 | C11: 1 | D11: Product (Money) | E11: /electropolished-welded-erw-pipes/ | F11: Electropolished Welded / ERW Pipes Manufacturer & Supplier | G11: Electropolished Welded / ERW Pipes Supplier India | H11: =LEN(G11) -> 49 | I11: Electropolished welded and ERW stainless steel pipes, ASTM A270 & A312. Bead-rolled and ID-polished options for sanitary and hygienic service. Get a quote. | J11: =LEN(I11) -> 155 | K11: electropolished erw pipes | L11: electropolished welded pipes | EP ERW tube | welded EP tubing | M11: 1500 | N11: Product; BreadcrumbList; FAQPage; Organization | O11: /products/ | P11: /asme-bpe-electropolished-tubes/, /astm-a270-electropolished-tubes/, top 3 industry pages, /request-a-quote/ | Q11: Spec-table + inline RFQ (grade, OD, WT, qty, Ra) + WhatsApp | R11: electropolished-welded-erw-pipes-sakshi-forge | S11: MUST include: spec table (OD/WT/length/Ra), chemical composition table, standards list, 6-8 FAQ block, 3 real photos of stock. | U11: Not started | V11: Not started | X11: No
A12: SF-009 | B12: P1 | C12: 1 | D12: Product (Money) | E12: /electropolished-pipe-fittings/ | F12: Electropolished Pipe Fittings Manufacturer & Supplier | G12: Electropolished Pipe Fittings — Elbows, Tees, Reducers | H12: =LEN(G12) -> 54 | I12: Electropolished SS 316L/304L fittings: elbows, tees, reducers, TC ferrules, bends. ASME BPE dimensions, SF4 EP finish, matched to your tube ID. Request a. | J12: =LEN(I12) -> 154 | K12: electropolished pipe fittings | L12: EP elbows | EP tees | EP reducers | electropolished sanitary fittings | M12: 1500 | N12: Product; BreadcrumbList; FAQPage; Organization | O12: /products/ | P12: /asme-bpe-electropolished-tubes/, /astm-a270-electropolished-tubes/, top 3 industry pages, /request-a-quote/ | Q12: Spec-table + inline RFQ (grade, OD, WT, qty, Ra) + WhatsApp | R12: electropolished-pipe-fittings-sakshi-forge | S12: MUST include: spec table (OD/WT/length/Ra), chemical composition table, standards list, 6-8 FAQ block, 3 real photos of stock. | U12: Not started | V12: Not started | X12: No
A13: SF-010 | B13: P1 | C13: 1 | D13: Product (Money) | E13: /internal-electropolished-pipes/ | F13: Internal (ID) Electropolished Pipes Manufacturer & Supplier | G13: Internal (ID) Electropolished Pipes | ID EP Pipe Supplier | H13: =LEN(G13) -> 57 | I13: Internally electropolished SS pipes where only the bore is EP finished — the cost-efficient choice for process lines. ID Ra 0.38 um, OD as-supplied or. | J13: =LEN(I13) -> 151 | K13: internal electropolished pipes | L13: ID electropolished stainless steel pipes | inside and outside electropolished pipes | M13: 1500 | N13: Product; BreadcrumbList; FAQPage; Organization | O13: /products/ | P13: /asme-bpe-electropolished-tubes/, /astm-a270-electropolished-tubes/, top 3 industry pages, /request-a-quote/ | Q13: Spec-table + inline RFQ (grade, OD, WT, qty, Ra) + WhatsApp | R13: internal-electropolished-pipes-sakshi-forge | S13: MUST include: spec table (OD/WT/length/Ra), chemical composition table, standards list, 6-8 FAQ block, 3 real photos of stock. | U13: Not started | V13: Not started | X13: No
A14: SF-011 | B14: P1 | C14: 1 | D14: Product (Money) | E14: /high-purity-stainless-steel-pipes/ | F14: High Purity Stainless Steel Pipes Manufacturer & Supplier | G14: High Purity Stainless Steel Pipes Supplier India | H14: =LEN(G14) -> 48 | I14: High purity SS pipes & tubes for pharma, biotech and semiconductor service. Low Ra electropolished bore, passivated, PMI verified, EN 10204 3.1 MTC. Get a. | J14: =LEN(I14) -> 155 | K14: high purity stainless steel pipes | L14: high purity EP tubes | high purity SS tubing | M14: 1500 | N14: Product; BreadcrumbList; FAQPage; Organization | O14: /products/ | P14: /asme-bpe-electropolished-tubes/, /astm-a270-electropolished-tubes/, top 3 industry pages, /request-a-quote/ | Q14: Spec-table + inline RFQ (grade, OD, WT, qty, Ra) + WhatsApp | R14: high-purity-stainless-steel-pipes-sakshi-forge | S14: MUST include: spec table (OD/WT/length/Ra), chemical composition table, standards list, 6-8 FAQ block, 3 real photos of stock. | U14: Not started | V14: Not started | X14: No
A15: SF-012 | B15: P1 | C15: 1 | D15: Product (Money) | E15: /ultra-high-purity-ep-tubes/ | F15: Ultra High Purity EP Tubes Manufacturer & Supplier | G15: Ultra High Purity EP Tubes | UHP Tubing India | H15: =LEN(G15) -> 45 | I15: UHP electropolished tubing for semiconductor gas lines and UPW loops. SEMI F19-referenced surface finishes, capped and double-bagged, cleanroom packed. | J15: =LEN(I15) -> 151 | K15: ultra high purity ep tubes | L15: UHP EP tubing | semiconductor EP tube | high purity gas line tube | M15: 1500 | N15: Product; BreadcrumbList; FAQPage; Organization | O15: /products/ | P15: /asme-bpe-electropolished-tubes/, /astm-a270-electropolished-tubes/, top 3 industry pages, /request-a-quote/ | Q15: Spec-table + inline RFQ (grade, OD, WT, qty, Ra) + WhatsApp | R15: ultra-high-purity-ep-tubes-sakshi-forge | S15: MUST include: spec table (OD/WT/length/Ra), chemical composition table, standards list, 6-8 FAQ block, 3 real photos of stock. | U15: Not started | V15: Not started | X15: No
... A79: SF-076 | B79: P2 | C79: 3 | D79: Category Hub | E79: /resources/ | F79: EP Pipe Charts, Calculators & Technical Resources | G79: EP Pipe Charts, Calculators & Spec Downloads | Sakshi Forge | H79: =LEN(G79) -> 59 | I79: Free tools for specifying electropolished pipe: Ra converter, ASME BPE SF chart, pipe size chart, weight calculator and downloadable spec sheets. | J79: =LEN(I79) -> 145 | K79: electropolished pipe technical resources | L79: ra converter | asme bpe surface finish chart | pipe size chart | M79: 600 | N79: CollectionPage; BreadcrumbList | O79: / | P79: All resource pages | Q79: Email-gated catalogue download | R79: ep-pipe-resources-tools | S79: These pages earn links and AI citations — treat as priority, not filler. | U79: Not started | V79: Not started | X79: No
A80: SF-077 | B80: P2 | C80: 3 | D80: Resource/tool | E80: /resources/ra-surface-finish-converter/ | F80: Ra Surface Finish Converter (um to uin) | G80: Ra Converter: Microns to Microinches (um to uin) | H80: =LEN(G80) -> 48 | I80: Free Ra surface roughness converter. Convert um to uin instantly and see which ASME BPE surface finish grade (SF1-SF6) your value falls into. | J80: =LEN(I80) -> 141 | K80: ra micron to microinch converter | M80: 900 | N80: Article; BreadcrumbList; FAQPage; HowTo | O80: /resources/ | P80: /electropolished-pipes/, /request-a-quote/ | Q80: Soft CTA: 'Need this spec supplied? Get a quote' | R80: ra-surface-finish-converter-chart | S80: Link-earning + AI-citation asset. Must contain a real data table with dual units. Keep the tool usable without email gating (except the catalogue). | U80: Not started | V80: Not started | X80: No
A81: SF-078 | B81: P2 | C81: 3 | D81: Resource/chart | E81: /resources/asme-bpe-surface-finish-chart/ | F81: ASME BPE Surface Finish Chart (SF1-SF6) | G81: ASME BPE Surface Finish Chart | SF1 to SF6 Ra Values | H81: =LEN(G81) -> 52 | I81: Complete ASME BPE surface finish table. SF1 20 uin/0.51 um, SF4 electropolished 15 uin/0.38 um, SF5, SF6 — mechanical vs electropolished designations. | J81: =LEN(I81) -> 150 | K81: asme bpe surface finish chart | M81: 900 | N81: Article; BreadcrumbList; FAQPage | O81: /resources/ | P81: /electropolished-pipes/, /request-a-quote/ | Q81: Soft CTA: 'Need this spec supplied? Get a quote' | R81: asme-bpe-surface-finish-chart-chart | S81: Link-earning + AI-citation asset. Must contain a real data table with dual units. Keep the tool usable without email gating (except the catalogue). | U81: Not started | V81: Not started | X81: No
A82: SF-079 | B82: P2 | C82: 3 | D82: Resource/chart | E82: /resources/ep-pipe-size-chart/ | F82: EP Pipe & Tube Size Chart (OD / WT / NB) | G82: Electropolished Pipe & Tube Size Chart | OD, WT, NB | H82: =LEN(G82) -> 51 | I82: EP pipe and tube size chart with OD, wall thickness, NB equivalents and weight per metre for 304L and 316L. Downloadable PDF included. | J82: =LEN(I82) -> 134 | K82: electropolished pipe size chart | M82: 900 | N82: Article; BreadcrumbList; FAQPage | O82: /resources/ | P82: /electropolished-pipes/, /request-a-quote/ | Q82: Soft CTA: 'Need this spec supplied? Get a quote' | R82: ep-pipe-size-chart-chart | S82: Link-earning + AI-citation asset. Must contain a real data table with dual units. Keep the tool usable without email gating (except the catalogue). | U82: Not started | V82: Not started | X82: No
A83: SF-080 | B83: P2 | C83: 3 | D83: Resource/tool | E83: /resources/ss-pipe-weight-calculator/ | F83: SS Pipe Weight Calculator | G83: Stainless Steel Pipe Weight Calculator | Kg per Metre | H83: =LEN(G83) -> 53 | I83: Calculate SS pipe and tube weight per metre from OD and wall thickness. Works for 304, 304L, 316 and 316L. Free instant calculator. | J83: =LEN(I83) -> 131 | K83: stainless steel pipe weight calculator | M83: 900 | N83: Article; BreadcrumbList; FAQPage; HowTo | O83: /resources/ | P83: /electropolished-pipes/, /request-a-quote/ | Q83: Soft CTA: 'Need this spec supplied? Get a quote' | R83: ss-pipe-weight-calculator-chart | S83: Link-earning + AI-citation asset. Must contain a real data table with dual units. Keep the tool usable without email gating (except the catalogue). | U83: Not started | V83: Not started | X83: No
A84: SF-081 | B84: P2 | C84: 4 | D84: Resource/commercial | E84: /resources/electropolished-pipe-price-list/ | F84: Electropolished Pipe Price List India | G84: Electropolished Pipe Price in India | Per Kg & Per Metre | H84: =LEN(G84) -> 56 | I84: What electropolished pipe costs in India and what drives the price — grade, Ra spec, ID vs ID+OD, wall thickness and order quantity. Get a live quote. | J84: =LEN(I84) -> 150 | K84: electropolished pipe price per kg | M84: 900 | N84: Article; BreadcrumbList; FAQPage | O84: /resources/ | P84: /electropolished-pipes/, /request-a-quote/ | Q84: Soft CTA: 'Need this spec supplied? Get a quote' | R84: electropolished-pipe-price-list-chart | S84: Link-earning + AI-citation asset. Must contain a real data table with dual units. Keep the tool usable without email gating (except the catalogue). | U84: Not started | V84: Not started | X84: No
A85: SF-082 | B85: P2 | C85: 4 | D85: Resource/comparison | E85: /resources/ep-vs-mechanical-polish-vs-pickled/ | F85: EP vs Mechanically Polished vs Pickled & Passivated | G85: Electropolished vs Mechanically Polished vs Pickled & | H85: =LEN(G85) -> 53 | I85: How electropolishing, mechanical polishing and pickling & passivation differ in Ra, corrosion resistance, cleanability and cost. Side-by-side comparison. | J85: =LEN(I85) -> 153 | K85: electropolished vs mechanically polished | M85: 900 | N85: Article; BreadcrumbList; FAQPage | O85: /resources/ | P85: /electropolished-pipes/, /request-a-quote/ | Q85: Soft CTA: 'Need this spec supplied? Get a quote' | R85: ep-vs-mechanical-polish-vs-pickled-chart | S85: Link-earning + AI-citation asset. Must contain a real data table with dual units. Keep the tool usable without email gating (except the catalogue). | U85: Not started | V85: Not started | X85: No
A86: SF-083 | B86: P2 | C86: 4 | D86: Resource/comparison | E86: /resources/astm-a270-vs-a269/ | F86: ASTM A270 vs ASTM A269 Comparison | G86: ASTM A270 vs ASTM A269 | Which Tubing Spec Do You Need? | H86: =LEN(G86) -> 55 | I86: ASTM A270 sanitary tubing vs ASTM A269 general service tubing — scope, sizes, finish, testing and when to specify each. Clear comparison table. | J86: =LEN(I86) -> 143 | K86: astm a270 vs a269 | M86: 900 | N86: Article; BreadcrumbList; FAQPage | O86: /resources/ | P86: /electropolished-pipes/, /request-a-quote/ | Q86: Soft CTA: 'Need this spec supplied? Get a quote' | R86: astm-a270-vs-a269-chart | S86: Link-earning + AI-citation asset. Must contain a real data table with dual units. Keep the tool usable without email gating (except the catalogue). | U86: Not started | V86: Not started | X86: No
A87: SF-084 | B87: P2 | C87: 4 | D87: Resource/comparison | E87: /resources/316l-vs-304l-ep-pipes/ | F87: SS 316L vs 304L EP Pipes | G87: SS 316L vs 304L EP Pipes | Which Grade to Specify | H87: =LEN(G87) -> 49 | I87: 316L vs 304L electropolished pipe: chemistry, corrosion resistance, chloride tolerance, cost and typical applications. Pick the right grade first time. | J87: =LEN(I87) -> 151 | K87: 316l vs 304l stainless steel pipe | M87: 900 | N87: Article; BreadcrumbList; FAQPage | O87: /resources/ | P87: /electropolished-pipes/, /request-a-quote/ | Q87: Soft CTA: 'Need this spec supplied? Get a quote' | R87: 316l-vs-304l-ep-pipes-chart | S87: Link-earning + AI-citation asset. Must contain a real data table with dual units. Keep the tool usable without email gating (except the catalogue). | U87: Not started | V87: Not started | X87: No
A88: SF-085 | B88: P2 | C88: 3 | D88: Resource/leadmagnet | E88: /resources/download-ep-pipe-catalogue/ | F88: Download EP Pipe Catalogue & Spec Sheet | G88: Download EP Pipe Catalogue & Spec Sheet (PDF) | H88: =LEN(G88) -> 45 | I88: Download the Sakshi Forge electropolished pipe catalogue — grades, sizes, Ra options, standards and test certificates. Free PDF, instant access. | J88: =LEN(I88) -> 144 | K88: electropolished pipe catalogue pdf | M88: 900 | N88: Article; BreadcrumbList; FAQPage | O88: /resources/ | P88: /electropolished-pipes/, /request-a-quote/ | Q88: Soft CTA: 'Need this spec supplied? Get a quote' | R88: download-ep-pipe-catalogue-chart | S88: Link-earning + AI-citation asset. Must contain a real data table with dual units. Keep the tool usable without email gating (except the catalogue). | U88: Not started | V88: Not started | X88: No
A89: SF-086 | B89: P2 | C89: 4 | D89: Resource/trust | E89: /resources/en-10204-31-mtc-sample/ | F89: Sample EN 10204 3.1 MTC | G89: Sample EN 10204 3.1 MTC for Electropolished Pipe | H89: =LEN(G89) -> 48 | I89: See exactly what an EN 10204 3.1 mill test certificate looks like for EP pipe — heat number, chemistry, mechanicals, Ra reading and PMI result. | J89: =LEN(I89) -> 143 | K89: en 10204 3.1 certificate sample | M89: 900 | N89: Article; BreadcrumbList; FAQPage | O89: /resources/ | P89: /electropolished-pipes/, /request-a-quote/ | Q89: Soft CTA: 'Need this spec supplied? Get a quote' | R89: en-10204-31-mtc-sample-chart | S89: Link-earning + AI-citation asset. Must contain a real data table with dual units. Keep the tool usable without email gating (except the catalogue). | U89: Not started | V89: Not started | X89: No
A90: SF-087 | B90: P2 | C90: 1 | D90: Trust/Conversion | E90: /about-sakshi-forge/ | F90: About Sakshi Forge | G90: About Sakshi Forge | EP Pipe Manufacturer, Mumbai | H90: =LEN(G90) -> 49 | I90: Sakshi Forge is an ISO 9001:2015 certified stainless steel manufacturer in Mumbai specialising in electropolished pipes, tubes and fittings for process. | J90: =LEN(I90) -> 152 | K90: electropolished pipe manufacturer mumbai | M90: 700 | N90: AboutPage; Organization | O90: / | P90: /electropolished-pipes/, /industries/ | Q90: Primary RFQ form | R90: sakshi-forge-about-sakshi-forge | S90: Conversion-critical. Certificates as real scanned images with descriptive alt text, NOT stock graphics. | U90: Not started | V90: Not started | X90: No
A91: SF-088 | B91: P1 | C91: 1 | D91: Trust/Conversion | E91: /quality-certifications/ | F91: Quality, ISO 9001:2015 & Test Certificates | G91: Quality & Certifications | ISO 9001:2015, MTC, PMI | H91: =LEN(G91) -> 50 | I91: Our quality system, ISO 9001:2015 certificate, EN 10204 3.1 mill test certificates, PMI reports and Ra profilometer records — all viewable here. | J91: =LEN(I91) -> 144 | K91: iso 9001 ep pipe manufacturer | M91: 700 | N91: WebPage; BreadcrumbList | O91: / | P91: /electropolished-pipes/, /industries/ | Q91: Primary RFQ form | R91: sakshi-forge-quality-certifications | S91: Conversion-critical. Certificates as real scanned images with descriptive alt text, NOT stock graphics. | U91: Not started | V91: Not started | X91: No
... A109: SF-106 | B109: P3 | C109: 4 | D109: Category Hub | E109: /blog/ | F109: Technical Insights on Electropolished Piping | G109: EP Pipe Technical Blog | Sakshi Forge | H109: =LEN(G109) -> 37 | I109: Engineering guidance on specifying, inspecting and installing electropolished stainless steel piping for pharma, dairy, food and semiconductor plants. | J109: =LEN(I109) -> 150 | K109: electropolished pipe blog | M109: 400 | N109: Blog; BreadcrumbList | O109: / | P109: All blog posts | Q109: Newsletter / catalogue download | R109: ep-pipe-technical-blog | S109: Paginated, 10 posts per page, self-referencing canonical per page. | U109: Not started | V109: Not started | X109: No

Sheet 03 Keyword Bank
A1: KEYWORD BANK — TRANSACTIONAL FOCUS
A2: Every keyword maps to exactly ONE url. Two pages targeting the same term cannibalise each other and both lose.
A3: # | B3: Keyword | C3: Intent Class | D3: Buyer Stage | E3: Mapped URL (one page only) | F3: Placement | G3: Competition Note
A4: 1 | B4: Electropolished Pipes | C4: Transactional-Head | D4: Ready to buy | E4: /electropolished-pipes/ | F4: H1 + first 100 words + title tag | G4: Both competitors rank here. Hardest terms — expect 6-9 months. Win on page depth + schema.
A5: 2 | B5: Electropolished SS Pipes | C5: Transactional-Head | D5: Ready to buy | E5: /electropolished-pipes/ | F5: H1 + first 100 words + title tag | G5: Both competitors rank here. Hardest terms — expect 6-9 months. Win on page depth + schema.
A6: 3 | B6: Electropolished Stainless Steel Pipes | C6: Transactional-Head | D6: Ready to buy | E6: /electropolished-pipes/ | F6: H1 + first 100 words + title tag | G6: Both competitors rank here. Hardest terms — expect 6-9 months. Win on page depth + schema.
A7: 4 | B7: EP Pipes | C7: Transactional-Head | D7: Ready to buy | E7: /electropolished-pipes/ | F7: H1 + first 100 words + title tag | G7: Both competitors rank here. Hardest terms — expect 6-9 months. Win on page depth + schema.
A8: 5 | B8: SS EP Pipes | C8: Transactional-Head | D8: Ready to buy | E8: /electropolished-pipes/ | F8: H1 + first 100 words + title tag | G8: Both competitors rank here. Hardest terms — expect 6-9 months. Win on page depth + schema.
A9: 6 | B9: Stainless Steel EP Pipes | C9: Transactional-Head | D9: Ready to buy | E9: /electropolished-pipes/ | F9: H1 + first 100 words + title tag | G9: Both competitors rank here. Hardest terms — expect 6-9 months. Win on page depth + schema.
A10: 7 | B10: Electropolished Tubes | C10: Transactional-Head | D10: Ready to buy | E10: /electropolished-tubes/ | F10: H1 + first 100 words + title tag | G10: Both competitors rank here. Hardest terms — expect 6-9 months. Win on page depth + schema.
A11: 8 | B11: SS Electropolished Tubes | C11: Transactional-Head | D11: Ready to buy | E11: /electropolished-tubes/ | F11: H1 + first 100 words + title tag | G11: Both competitors rank here. Hardest terms — expect 6-9 months. Win on page depth + schema.
A12: 9 | B12: Electropolished Pipe Manufacturer | C12: Transactional-Buyer | D12: Vendor selection | E12: /electropolished-pipes/ | F12: Title tag + H2 'Why buy from us' | G12: Highest commercial value. IndiaMART dominates page 1 — a directory listing is needed alongside the page.
A13: 10 | B13: Electropolished Pipe Supplier | C13: Transactional-Buyer | D13: Vendor selection | E13: /electropolished-pipes/ | F13: Title tag + H2 'Why buy from us' | G13: Highest commercial value. IndiaMART dominates page 1 — a directory listing is needed alongside the page.
A14: 11 | B14: Electropolished Pipe Stockist | C14: Transactional-Buyer | D14: Vendor selection | E14: /electropolished-pipes/ | F14: Title tag + H2 'Why buy from us' | G14: Highest commercial value. IndiaMART dominates page 1 — a directory listing is needed alongside the page.
A15: 12 | B15: Electropolished SS Pipe Manufacturer | C15: Transactional-Buyer | D15: Vendor selection | E15: /electropolished-pipes/ | F15: Title tag + H2 'Why buy from us' | G15: Highest commercial value. IndiaMART dominates page 1 — a directory listing is needed alongside the page.
... A58: 55 | B58: Ultra High Purity EP Tubes | C58: Transactional-Spec | D58: Spec locked | E58: /ultra-high-purity-ep-tubes/ | F58: H2 + Ra table | G58: Low volume, very high intent. Cheap wins that convert.
B60: CITY-MODIFIED TRANSACTIONAL EXPANSIONS
B61: electropolished pipe manufacturer in hyderabad | C61: Transactional-Local | D61: Ready to buy | E61: /electropolished-pipe-supplier-hyderabad/ | F61: H1 + local dispatch section | G61: Priority 1 cluster: Pharma / API / Bulk Drugs / Biotech / Breweries. Only build if you can write genuinely local content.
B62: electropolished pipe supplier in hyderabad | C62: Transactional-Local | D62: Ready to buy | E62: /electropolished-pipe-supplier-hyderabad/ | F62: H1 + local dispatch section | G62: Priority 1 cluster: Pharma / API / Bulk Drugs / Biotech / Breweries. Only build if you can write genuinely local content.
B63: ss 316l ep pipes in hyderabad | C63: Transactional-Local | D63: Ready to buy | E63: /ss-316l-electropolished-pipes-in-hyderabad/ | F63: H1 + local dispatch section | G63: Priority 1 cluster: Pharma / API / Bulk Drugs / Biotech / Breweries. Only build if you can write genuinely local content.
B64: electropolished pipe manufacturer in pune | C64: Transactional-Local | D64: Ready to buy | E64: /electropolished-pipe-supplier-pune/ | F64: H1 + local dispatch section | G64: Priority 1 cluster: Pharma / Dairy / Food & Beverage / Biotech. Only build if you can write genuinely local content.
B65: electropolished pipe supplier in pune | C65: Transactional-Local | D65: Ready to buy | E65: /electropolished-pipe-supplier-pune/ | F65: H1 + local dispatch section | G65: Priority 1 cluster: Pharma / Dairy / Food & Beverage / Biotech. Only build if you can write genuinely local content.
B66: ss 316l ep pipes in pune | C66: Transactional-Local | D66: Ready to buy | E66: /ss-316l-electropolished-pipes-in-pune/ | F66: H1 + local dispatch section | G66: Priority 1 cluster: Pharma / Dairy / Food & Beverage / Biotech. Only build if you can write genuinely local content.
B67: electropolished pipe manufacturer in ahmedabad | C67: Transactional-Local | D67: Ready to buy | E67: /electropolished-pipe-supplier-ahmedabad/ | F67: H1 + local dispatch section | G67: Priority 1 cluster: Pharma / API / Dairy / Food Processing. Only build if you can write genuinely local content.
B68: electropolished pipe supplier in ahmedabad | C68: Transactional-Local | D68: Ready to buy | E68: /electropolished-pipe-supplier-ahmedabad/ | F68: H1 + local dispatch section | G68: Priority 1 cluster: Pharma / API / Dairy / Food Processing. Only build if you can write genuinely local content.
B69: ss 316l ep pipes in ahmedabad | C69: Transactional-Local | D69: Ready to buy | E69: /ss-316l-electropolished-pipes-in-ahmedabad/ | F69: H1 + local dispatch section | G69: Priority 1 cluster: Pharma / API / Dairy / Food Processing. Only build if you can write genuinely local content.
B70: electropolished pipe manufacturer in bengaluru | C70: Transactional-Local | D70: Ready to buy | E70: /electropolished-pipe-supplier-bengaluru/ | F70: H1 + local dispatch section | G70: Priority 2 cluster: Biotech / Biopharma / Vaccines / Food Processing. Only build if you can write genuinely local content.
B71: electropolished pipe supplier in bengaluru | C71: Transactional-Local | D71: Ready to buy | E71: /electropolished-pipe-supplier-bengaluru/ | F71: H1 + local dispatch section | G71: Priority 2 cluster: Biotech / Biopharma / Vaccines / Food Processing. Only build if you can write genuinely local content.
B72: ss 316l ep pipes in bengaluru | C72: Transactional-Local | D72: Ready to buy | E72: /ss-316l-electropolished-pipes-in-bengaluru/ | F72: H1 + local dispatch section | G72: Priority 2 cluster: Biotech / Biopharma / Vaccines / Food Processing. Only build if you can write genuinely local content.
... B102: ss 316l ep pipes in mumbai | C102: Transactional-Local | D102: Ready to buy | E102: /ss-316l-electropolished-pipes-in-mumbai/ | F102: H1 + local dispatch section | G102: Priority 1 cluster: Pharma / Chemicals / Food / Head Office. Only build if you can write genuinely local content.

Sheet 04 Page Templates
A1: PAGE TEMPLATES — HEADING STRUCTURE & MANDATORY BLOCKS
A2: Follow the skeleton for the page type in column D of the Page Master. Consistency here is what makes the silo readable to Google.
A3: Page Type | B3: Heading Skeleton (H1 / H2 / H3) | C3: Mandatory On-Page Blocks | D3: Conversion Placement | E3: Never Do This
A4: Product (Money) | B4: H1: {Product} Manufacturer & Supplier H2: What is {product} / who it is for H2: Technical Specifications → TABLE H2: Grades & Chemical Composition → TABLE H2: Surface Finish & Ra Options → TABLE H2: Standards We Certify To H2: Industries & Applications H3: one per top 4 industries (linked) H2: Testing, Inspection & Documentation H2: Packing, Marking & Dispatch H2: Frequently Asked Questions (6-8 Q) H2: Request a Quote | C4: · Spec table: OD, WT, length, grade, Ra (um AND uin) · Chemical composition table for 304L and 316L · Standards list with the real scope of each · 3+ genuine photographs of actual stock, not stock imagery · 6-8 FAQ with FAQPage schema · MOQ, lead time and payment terms stated plainly · EN 10204 3.1 MTC mention with link to sample | D4: · Sticky 'Get Quote' button on scroll · Inline RFQ after the spec table · WhatsApp float bottom-right · Phone number in header, click-to-call on mobile | E4: · Do not pad with a list of 50 city names · Do not copy competitor spec tables verbatim · Do not publish without real photos · Do not gate the spec table behind a form
A5: Industry | B5: H1: Electropolished Pipes for the {Industry} Industry H2: Why {industry} plants specify electropolished pipe H2: Systems we supply into H3: one per system (CIP, SIP, WFI, etc.) H2: Typical Specification We Supply → TABLE H2: Applicable Standards H2: Common failure modes we design out H2: What we need from you to quote H2: FAQs (5-6 Q) H2: Request a Quote | C5: · 'Typical spec' table: grade / Ra / standard / system · 2 short application scenarios written as a plant engineer would describe them · Link to the 3 most relevant product pages · Sector-specific spec-sheet download | D5: · RFQ block phrased for that sector ('Send your line list / P&ID extract') · Download spec sheet (email capture) | E5: · Do not write generic 'we are the best' copy · Do not reuse the same 2 paragraphs across industries · Do not claim client names you cannot evidence
A6: Standard | B6: H1: {Standard} — Scope, Grades and Ordering H2: What {standard} actually covers H2: Dimensional range → TABLE H2: Grades permitted H2: Surface finish requirements → TABLE H2: Testing & certification required H2: How to write it on your PO H2: {Standard} vs {nearest alternative} → TABLE H2: FAQs H2: Order to this specification | C6: · Accurate scope statement — engineers verify this · Dimensional and finish tables in dual units · A worked 'how to write the PO line' example · Comparison table against the nearest standard | D6: · 'Order to this spec' RFQ with the standard pre-filled | E6: · NEVER state a standard's scope from memory. Verify it. One wrong figure destroys credibility with a QA buyer. · Do not reproduce the standard's text — summarise it
A7: City | B7: H1: Electropolished Pipe Supplier in {City} H2: Industrial areas we deliver into H2: Sectors we supply in {City} H2: Stock, lead time and dispatch H2: What we supply into {City} → TABLE H2: FAQs (3-4, locally framed) H2: Get a quote delivered to {City} | C7: · NAMED industrial estates (see sheet 09) · Realistic dispatch lead time and transport mode · 1-2 anonymised local supply examples · LocalBusiness schema with correct areaServed · Minimum 500 words of genuinely city-specific text | D7: · 'Dispatch to {City}' RFQ · Click-to-call and WhatsApp | E7: · NEVER spin one template across cities · Do not invent a local office you do not have · Do not claim to be 'based in' a city you are not · If you cannot write it uniquely, do not build it
A8: City x Product / Industry x City | B8: H1: {Product} in {City} OR EP Pipes for {Industry} Plants in {City} H2: The {City} {industry} cluster and what it needs H2: Specification we supply there → TABLE H2: Stock position and lead time H2: Related products H2: FAQs H2: Request a quote | C8: · Must differ from BOTH its parent city page and its parent product page by at least 60% of body text · Reference the actual cluster by name · Canonical points to itself (not the parent) | D8: · Local RFQ block | E8: · PHASE 4 ONLY — do not build these until Phase 1-3 pages are indexed and ranking · If in doubt, build fewer. Scaled thin pages are the single biggest domain-level risk in this plan
A9: Resource / Tool | B9: H1: {Tool or chart name} H2: The tool / the chart itself (above the fold) H2: How to read it H2: Worked example H2: Related standards H2: FAQs Soft CTA: 'Need this supplied? Get a quote' | C9: · A real, working data table or calculator · Dual units throughout (um AND uin, mm AND inch) · Downloadable PDF version · Cite the source standard for every figure | D9: · Soft CTA only — do not interrupt the tool · Catalogue download may capture email | E9: · Do not gate the tool behind a form · Do not put ads or popups over a calculator · Do not publish a figure you have not verified
A10: Blog | B10: H1: {Article title} H2: The short answer (first 100 words) H2-H2-H2: the substance, one idea each H2: Practical checklist → TABLE or list H2: FAQs Author box with real name + credentials | C10: · Answer the question in the first 100 words — this is what AI assistants extract and cite · At least one original table or diagram · Named author with a real engineering credential · Published and modified dates visible | D10: · End-of-post RFQ block · One contextual link to a product page mid-article | E10: · Do not publish AI-spun filler · Do not publish without a named human author · Do not chase volume over accuracy
A11: Trust / Conversion | B11: H1: {Page name} H2: The substance (certificates, process, contact) H2: What you receive with every order H2: Next step | C11: · Real scanned certificates with descriptive alt text · Real factory and process photographs · Full NAP: name, address, phone — identical everywhere · Sample EN 10204 3.1 MTC (redacted) | D11: · The RFQ form is the page | E11: · Do not use stock photography of someone else's factory · Do not display an ISO logo without the certificate · Do not show client logos you cannot evidence

Sheet 05 Internal Linking
A1: INTERNAL LINKING RULES — THE SILO
A2: This is where most of the ranking benefit sits. A page with no internal links pointing at it will not rank, however good the content is.
A3: Rule # | B3: From (page type) | C3: To (page type) | D3: How many links | E3: Anchor text pattern | F3: Why it matters
A4: 1 | B4: Homepage | C4: All 12 Product pages | D4: 12 | E4: Exact product name — 'SS 316L Electropolished Pipes' | F4: Passes the most authority to the money pages. Put these in a visible product grid, not just the footer.
A5: 2 | B5: Homepage | C5: Top 5 Industry pages | D5: 5 | E5: 'EP pipes for pharma', 'EP pipes for dairy' | F5: Signals topical breadth and routes buyers by their own vocabulary.
A6: 3 | B6: Homepage | C6: /request-a-quote/ | D6: 1 (+ sticky) | E6: 'Request a Quote' | F6: The single most important conversion path on the site.
A7: 4 | B7: Product page | C7: Related product pages | D7: 3-4 | E7: The related product's exact name | F7: Keeps buyers inside the product silo and spreads authority across it.
A8: 5 | B8: Product page | C8: Matching standard pages | D8: 2-3 | E8: 'ASTM A270 sanitary tubing', 'ASME BPE SF4' | F8: Standards pages are where technically-qualified buyers land. Connect them.
A9: 6 | B9: Product page | C9: Top 3 relevant Industry pages | D9: 3 | E9: 'used in WFI distribution loops' (contextual) | F9: Contextual mid-body links outperform navigation links.
A10: 7 | B10: Industry page | C10: Product pages | D10: 3 | E10: Exact product name | F10: Routes a problem-aware visitor to something they can actually buy.
A11: 8 | B11: Industry page | C11: Relevant Resource page | D11: 1-2 | E11: 'ASME BPE surface finish chart' | F11: Resource pages attract links; passing that authority into industry pages compounds it.
A12: 9 | B12: Standard page | C12: Product pages | D12: 2-3 | E12: Exact product name | F12: Converts specification research into a product enquiry.
A13: 10 | B13: City page | C13: Matching Industry page | D13: 1-2 | E13: 'pharma EP pipe specification' | F13: Gives a thin page type real topical support.
A14: 11 | B14: City page | C14: /electropolished-pipes/ | D14: 1 | E14: 'electropolished pipes' | F14: Every city page must feed the main money page.
A15: 12 | B15: Blog post | C15: Product + Resource pages | D15: 3-4 | E15: Contextual, varied, never 'click here' | F15: Blog authority is only useful if it flows to commercial pages.
... A18: 15 | B18: Footer | C18: Hub pages only | D18: 6-8 | E18: Section names | F18: Do NOT stuff 50 city links into the footer. That is the pattern Google penalises.
A21: ANCHOR TEXT RULES
A22: Vary the anchor text. If 40 pages all link to /electropolished-pipes/ with the identical anchor, that reads as manipulation.
A23: Roughly: 50% exact or near-exact keyword, 30% partial or descriptive, 20% natural phrase inside a sentence.
A24: Never use 'click here', 'read more', or a bare URL as anchor text — they pass no topical signal.
A25: Link from inside body copy wherever possible. A link in a paragraph counts for more than one in a nav or footer.
A26: Every page in the Page Master must have at least 3 internal links pointing TO it. Orphan pages do not get crawled properly.

Sheet 06 Schema Markup
A1: SCHEMA MARKUP — COPY-PASTE JSON-LD
A2: Wrap each block in <script type="application/ld+json"> ... </script>. Validate EVERY page before marking it live.
A3: Schema Type | B3: Apply To | C3: JSON-LD (paste in <head>, swap the {{ }} values) | D3: Validate At
A4: Organization | B4: Homepage only — once, sitewide | C4: { "@context": "https://schema.org", "@type": "Organization", "name": "Sakshi Forge", "url": "https://steelmanufacturer.in/", "logo": "https://steelmanufacturer.in/logo.png", "description": "ISO 9001:2015 certified manufacturer of electropolished stainless steel pipes, tubes and fittings.", "address": { "@type": "PostalAddress", "streetAddress": "{{STREET}}", "addressLocality": "Mumbai", "addressRegion": "Maharashtra", "postalCode": "{{PIN}}", "addressCountry": "IN" }, "contactPoint": { "@type": "ContactPoint", "telephone": "{{+91XXXXXXXXXX}}", "contactType": "sales", "areaServed": "IN", "availableLanguage": ["en","hi"] }, "sameAs": ["{{LINKEDIN_URL}}","{{INDIAMART_URL}}"] } | D4: search.google.com/test/rich-results
A5: Product | B5: All 12 product pages + City x Product | C5: { "@context": "https://schema.org", "@type": "Product", "name": "{{PRODUCT NAME}}", "description": "{{META DESCRIPTION FROM PAGE MASTER}}", "sku": "{{INTERNAL SKU}}", "brand": { "@type": "Brand", "name": "Sakshi Forge" }, "manufacturer": { "@type": "Organization", "name": "Sakshi Forge" }, "material": "Stainless Steel 316L / 304L", "image": ["https://steelmanufacturer.in/img/{{IMG}}.jpg"], "additionalProperty": [ { "@type": "PropertyValue", "name": "Surface Finish", "value": "Ra 0.38 um (15 uin) - ASME BPE SF4" }, { "@type": "PropertyValue", "name": "Standard", "value": "ASTM A270 / ASTM A312" }, { "@type": "PropertyValue", "name": "Certification", "value": "EN 10204 3.1 MTC" } ], "offers": { "@type": "AggregateOffer", "priceCurrency": "INR", "lowPrice": "{{LOW}}", "highPrice": "{{HIGH}}", "availability": "https://schema.org/InStock", "seller": { "@type": "Organization", "name": "Sakshi Forge" } } } | D5: search.google.com/test/rich-results
A6: FAQPage | B6: Every product, industry, standard and city page | C6: { "@context": "https://schema.org", "@type": "FAQPage", "mainEntity": [ { "@type": "Question", "name": "{{QUESTION 1 - use the exact wording of the on-page heading}}", "acceptedAnswer": { "@type": "Answer", "text": "{{ANSWER 1 - must match the visible on-page text}}" } }, { "@type": "Question", "name": "{{QUESTION 2}}", "acceptedAnswer": { "@type": "Answer", "text": "{{ANSWER 2}}" } } ] } | D6: search.google.com/test/rich-results
A7: BreadcrumbList | B7: Every page except the homepage | C7: { "@context": "https://schema.org", "@type": "BreadcrumbList", "itemListElement": [ { "@type": "ListItem", "position": 1, "name": "Home", "item": "https://steelmanufacturer.in/" }, { "@type": "ListItem", "position": 2, "name": "{{SECTION}}", "item": "https://steelmanufacturer.in/{{section}}/" }, { "@type": "ListItem", "position": 3, "name": "{{PAGE}}", "item": "https://steelmanufacturer.in/{{page}}/" } ] } | D7: search.google.com/test/rich-results
A8: LocalBusiness | B8: All 14 city pages + /contact/ | C8: { "@context": "https://schema.org", "@type": "LocalBusiness", "name": "Sakshi Forge", "image": "https://steelmanufacturer.in/logo.png", "url": "https://steelmanufacturer.in/electropolished-pipe-supplier-{{city-slug}}/", "telephone": "{{+91XXXXXXXXXX}}", "priceRange": "INR", "address": { "@type": "PostalAddress", "streetAddress": "{{STREET}}", "addressLocality": "Mumbai", "addressRegion": "Maharashtra", "postalCode": "{{PIN}}", "addressCountry": "IN" }, "areaServed": { "@type": "City", "name": "{{CITY NAME}}" }, "openingHoursSpecification": { "@type": "OpeningHoursSpecification", "dayOfWeek": ["Monday","Tuesday","Wednesday","Thursday","Friday","Saturday"], "opens": "10:00", "closes": "19:00" } } | D8: search.google.com/test/rich-results
A9: BlogPosting | B9: All 12 blog posts | C9: { "@context": "https://schema.org", "@type": "BlogPosting", "headline": "{{TITLE}}", "description": "{{META DESCRIPTION}}", "author": { "@type": "Person", "name": "{{REAL ENGINEER NAME}}", "jobTitle": "{{e.g. Quality Head}}", "worksFor": { "@type": "Organization", "name": "Sakshi Forge" } }, "publisher": { "@type": "Organization", "name": "Sakshi Forge", "logo": { "@type": "ImageObject", "url": "https://steelmanufacturer.in/logo.png" } }, "datePublished": "{{YYYY-MM-DD}}", "dateModified": "{{YYYY-MM-DD}}", "mainEntityOfPage": "{{FULL URL}}" } | D9: search.google.com/test/rich-results
A11: RULES
A12: FAQ schema answers MUST match the visible text on the page word for word. Mismatched schema is a manual-action risk.
A13: Do not add AggregateRating or Review schema unless you have genuine, verifiable customer reviews. Fake review markup is penalised.
A14: Multiple schema types on one page is correct — e.g. a product page carries Product + BreadcrumbList + FAQPage.
A15: Validate every single page before marking it Live. One malformed block can suppress rich results across the section.
A16: Keep the {{PLACEHOLDER}} values in a single config file so the developer swaps them once, not 106 times.

Sheet 07 Technical SEO
A1: TECHNICAL SEO CHECKLIST
A2: Item 1 is urgent and blocks everything else. Work in order.
A3: # | B3: Item | C3: What exactly to do | D3: Owner | E3: Priority | F3: Done?
A4: 1 | B4: INDEXATION — DO THIS TODAY | C4: Confirm steelmanufacturer.in actually resolves publicly and returns HTTP 200. Then verify the domain in Google Search Console, check for a stray 'noindex' meta tag or an X-Robots-Tag header, and check robots.txt is not blocking crawl. Research indicates the site currently returns no results in Google at all — until this is fixed, nothing else in this workbook can produce a single visitor. | D4: Developer | E4: URGENT | F4: No
A5: 2 | B5: robots.txt | C5: Serve at /robots.txt. Allow all crawlable content, disallow /wp-admin/ (except admin-ajax.php), /cart/, /?s=, and any staging path. Declare the sitemap: 'Sitemap: https://steelmanufacturer.in/sitemap_index.xml'. | D5: Developer | E5: P1 | F5: No
A6: 3 | B6: XML sitemap | C6: Generate via Rank Math or Yoast. Include all 106 pages, exclude tag/author/attachment archives. Submit in Search Console and re-submit after each phase. | D6: Developer | E6: P1 | F6: No
A7: 4 | B7: Canonical tags | C7: Self-referencing canonical on every page. City x Product pages canonical to THEMSELVES, not to the parent product page — otherwise they will not rank at all. | D7: Developer | E7: P1 | F7: No
A8: 5 | B8: HTTPS + redirects | C8: Force HTTPS. One canonical host (www or non-www, pick one). 301 every variant. No redirect chains longer than one hop. | D8: Developer | E8: P1 | F8: No
A9: 6 | B9: URL structure | C9: Lowercase, hyphenated, no trailing index.php, consistent trailing slash. Match the Page Master column E exactly — changing a slug later costs you the ranking. | D9: Developer | E9: P1 | F9: No
A10: 7 | B10: Title & meta implementation | C10: Pull the values from Page Master columns G and I literally. Do not let the SEO plugin auto-generate over them. | D10: Developer | E10: P1 | F10: No
A11: 8 | B11: Heading hierarchy | C11: Exactly one H1 per page. No skipping levels. Do not use headings for styling. | D11: Developer | E11: P1 | F11: No
A12: 9 | B12: Image optimisation | C12: WebP, max 1600px wide, under 150KB. Descriptive filenames from Page Master column R. Alt text describing the actual image. Lazy-load everything below the fold. | D12: Developer | E12: P1 | F12: No
A13: 10 | B13: Core Web Vitals | C13: Target LCP under 2.5s, INP under 200ms, CLS under 0.1. Defer non-critical JS, inline critical CSS, preload the hero image, set explicit width/height on every image. | D13: Developer | E13: P1 | F13: No
A14: 11 | B14: Mobile | C14: Most Indian B2B buyers will open this on a phone. Test every template at 360px. Tap targets 48px minimum. Click-to-call in the header. | D14: Developer | E14: P1 | F14: No
A15: 12 | B15: Google Search Console | C15: Verify, submit sitemap, then check Coverage weekly. Watch for 'Discovered - currently not indexed' — that means thin content. | D15: Akshat | E15: P1 | F15: No
... A24: 21 | B24: Duplicate content audit | C24: Before Phase 4 goes live, run every new page through a similarity check against its siblings. Anything over 40% similar gets rewritten or dropped. | D24: Both | E24: P1 | F24: No

Sheet 08 Build Phases
A1: BUILD PHASES & SEQUENCING
A2: Sequence matters more than speed. Each phase has a gate — meeting it is what stops the site being penalised later.
A3: Phase | B3: Weeks | C3: Pages | D3: What gets built | E3: Effort | F3: Impact | G3: Gate — do not proceed until
